Workbook

Sheet eMPC_vs_iPSC
A1: Parameters: | C1: padj < | D1: 0.05
A3: Include in signature? | B3: include_apriori | C3: Stage-associated side of contrast (auto from NES sign) | D3: Biological category | E3: Redundancy | F3: pathway | G3: pathway_clean | H3: pval | I3: padj | J3: log2err | K3: ES | L3: NES | M3: size | N3: leadingEdge
F4: GOBP_2_OXOGLUTARATE_METABOLIC_PROCESS | G4: 2 Oxoglutarate Metabolic Process | H4: 0.70825688 | I4: 0.86742851 | J4: 0.057609111 | K4: -0.311302 | L4: -0.81137784 | M4: 15 | N4: GPT2, L2HGDH, GOT2, OGDHL, PHYH, GOT1
F5: GOBP_3_UTR_MEDIATED_MRNA_DESTABILIZATION | G5: 3 Utr Mediated Mrna Destabilization | H5: 0.81465517 | I5: 0.92256026 | J5: 0.058593757 | K5: 0.26216969 | L5: 0.73866533 | M5: 19 | N5: ZFP36L2, RBM24, ZC3H12C, KHNYN, KHSRP
F6: GOBP_3_UTR_MEDIATED_MRNA_STABILIZATION | G6: 3 Utr Mediated Mrna Stabilization | H6: 0.56424581 | I6: 0.79914433 | J6: 0.069283647 | K6: -0.32953146 | L6: -0.93641117 | M6: 20 | N6: RBM47, ADARB2, RBM38, YBX3
F7: GOBP_ACETYL_COA_BIOSYNTHETIC_PROCESS | G7: Acetyl Coa Biosynthetic Process | H7: 0.084388186 | I7: 0.36994874 | J7: 0.22496609 | K7: 0.48108066 | L7: 1.3814798 | M7: 21 | N7: PDK1, ACSS2
F8: GOBP_ACETYL_COA_METABOLIC_PROCESS | G8: Acetyl Coa Metabolic Process | H8: 0.14699332 | I8: 0.46519397 | J8: 0.17232434 | K8: 0.38815004 | L8: 1.2792048 | M8: 35 | N8: PDK1, AADAT, MVK, ACSS2, MVD, HMGCS1, HMGCR, FASN, ACLY
F9: GOBP_ACIDIC_AMINO_ACID_TRANSPORT | G9: Acidic Amino Acid Transport | H9: 0.047202797 | I9: 0.2872576 | J9: 0.2765006 | K9: -0.43259495 | L9: -1.4229503 | M9: 40 | N9: SLC1A1, STXBP1, SLC6A6, SLC1A3, PIANP, LRRC8D, SLC38A2, KCNK1, ATP1A2, ABAT, UCP2, GIPC1, LRRC8B, TTYH3, SLC1A5
F10: GOBP_ACROSOME_ASSEMBLY | G10: Acrosome Assembly | H10: 0.91926606 | I10: 0.97420963 | J10: 0.04558782 | K10: -0.25126378 | L10: -0.65489418 | M10: 15 | N10: CCDC136, AGFG1, PLA2G3, DCAF17
F11: GOBP_ACROSOME_REACTION | G11: Acrosome Reaction | H11: 0.14571949 | I11: 0.46298469 | J11: 0.15524197 | K11: -0.50498624 | L11: -1.3433074 | M11: 16 | N11: SYT6, CACNA1H, RAB3A, STXBP1, UNC13B
F12: GOBP_ACTIN_FILAMENT_BASED_MOVEMENT | G12: Actin Filament Based Movement | H12: 0.40554156 | I12: 0.70108497 | J12: 0.10434395 | K12: 0.2584769 | L12: 1.0225836 | M12: 87 | N12: DSP, GJA1, CAMK2D, MYO1B, TTN, ZEB2, PARVA, DLG1, EPDR1, MYH6, WIPF1, LIMCH1, ACTC1, EMP2
F13: GOBP_ACTIN_FILAMENT_BUNDLE_ORGANIZATION | G13: Actin Filament Bundle Organization | H13: 0.14192496 | I13: 0.45836226 | J13: 0.1482615 | K13: -0.29125456 | L13: -1.1751483 | M13: 139 | N13: EPHA1, DPYSL3, SFRP1, ADD2, FHDC1, PAWR, RHPN2, EZR, CGNL1, PDLIM1, FHOD1, RHOD, ARHGEF5, ARHGEF10L, PAK1, TPM1, PLS1, ESPN
F14: GOBP_ACTIN_FILAMENT_DEPOLYMERIZATION | G14: Actin Filament Depolymerization | H14: 0.35990888 | I14: 0.66940686 | J14: 0.10552094 | K14: 0.30063265 | L14: 1.0462219 | M14: 44 | N14: EPS8, CFL2, ADD1, F2RL1, RDX, LIMA1, SPECC1L, SPTBN2, TMOD3, PIK3CA, DMTN, TWF1, CAPZA1, PPP1R9B, TMOD2, TRIOBP
F15: GOBP_ACTIN_FILAMENT_ORGANIZATION | G15: Actin Filament Organization | H15: 0.040540541 | I15: 0.26694638 | J15: 0.2765006 | K15: -0.27432675 | L15: -1.2344991 | M15: 342 | N15: EPHA1, DPYSL3, SFRP1, ADD2, FHDC1, RND2, CDC42EP3, PAWR, RHPN2, COBL, CYFIP2, EZR, CGNL1, PDLIM1, CXCL12, VASP, MYO1C, FHOD1, MYO5B, RHOD, MYO5C, ARHGEF5, ARHGEF10L, MYO1E, BCAR1, PAK1, TMSB4X, TPM1, ADD3, SH3BP4, PLS1, GDPD2, WIPF3, SHROOM3, ESPN, PACSIN1, MAD2L2, SEMA5A, CORO2A, MYO5A, DIAPH2, ELMO3, CTTN, JMY, CDC42EP2, CORO1A, SPTBN1, CD2AP, RND1, PXN, PICK1, SHROOM2, PPP1R9A, SPTB, ARHGAP18, F11R, KANK1, RHPN1, RND3, RAPGEF3, MYO6, PPM1E, PLEKHH2, NEB, RAB40B, FCHSD1, SHROOM4, GIPC1, AIF1L, SPIRE1, LIMK1, ASAP3, IQGAP2, TWF2, SPTAN1, ABI2, RAC3, ARRB1, SHTN1, TMOD1, CX3CL1, PLEC, BBS4, TJP1, SPIRE2, CNN2, HAX1, SYNPO, SVIL, SDC4, KPTN, PFN1
... F45: GOBP_ALCOHOL_BIOSYNTHETIC_PROCESS | G45: Alcohol Biosynthetic Process | H45: 0.010877798 | I45: 0.12598187 | J45: 0.3807304 | K45: 0.36191575 | L45: 1.4868648 | M45: 99 | N45: CYP51A1, ABCG1, QDPR, DAB2, GNAI1, MVK, IDI1, HSD17B7, BMP2, H6PD, MVD, NSDHL, HMGCS1, LSS, MBTPS2, HMGCR, INSIG1, DHCR24, EBP, PRKACA, IMPA1, DHCR7, ACLY, PARK7, CYP27A1, SQLE, MSMO1, FDPS, PTH1R
A46: yes_final | B46: =VLOOKUP(G46,decisions1!A:B,2,FALSE) -> yes_apriori | C46: =IF(L46>0,"eMPC-side","iPSC-side") -> eMPC-side | D46: embryonic patterning and morphogenesis | E46: =VLOOKUP(F46,collapsed1!A:J,10,FALSE) -> main | F46: GOBP_ANTERIOR_POSTERIOR_PATTERN_SPECIFICATION | G46: Anterior Posterior Pattern Specification | H46: 3.9301429e-09 | I46: 2.2373374e-06 | J46: 0.7614608 | K46: 0.52976756 | L46: 2.2520977 | M46: 130 | N46: AXIN2, NKD1, PLXNA2, DLL3, HES6, WLS, MLLT3, PCSK5, FOXH1, WNT5A, HOXC4, MSX1, LFNG, HOXA5, LEF1, HOXB6, HOXB5, BHLHE40, BMP2, TBX3, ZEB2, GPC3, HOXB4, HIPK2, HOXA3, POFUT1, GBX2, NOTCH1, TSHZ1, HOXA9, HOXB8, HOXB7, HOXB3, HOXB9, HOXB2, ALDH1A2, FOXC1, DKK1, HOXC6, TGFBR1, GLI3, BMP4, POGLUT1
A47: no_redundant_auto | B47: =VLOOKUP(G47,decisions1!A:B,2,FALSE) -> no_redundant | C47: =IF(L47>0,"eMPC-side","iPSC-side") -> eMPC-side | D47: cardiovascular and endocardial development | E47: =VLOOKUP(F47,collapsed1!A:J,10,FALSE) -> redundant | F47: GOBP_HEART_VALVE_MORPHOGENESIS | G47: Heart Valve Morphogenesis | H47: 2.4556796e-06 | I47: 0.00047177939 | J47: 0.62725674 | K47: 0.61981661 | L47: 2.2112741 | M47: 50 | N47: AXIN2, ROBO1, SNAI1, ROCK2, CDH11, EFNA1, BMP2, STRA6, ADAMTS19, NOTCH1, DCHS1, ADAMTS9, BMP4, SNAI2, EMILIN1, BMPR2
F48: GOBP_ALDEHYDE_METABOLIC_PROCESS | G48: Aldehyde Metabolic Process | H48: 0.48691099 | I48: 0.75266235 | J48: 0.073438141 | K48: -0.28981672 | L48: -0.99166711 | M48: 48 | N48: TKT, CACNA1H, PDXK, HAGH, ALDH1B1, AKR1A1, TALDO1, MGAT4A, ALDH3A2, EDNRB, DKK3, AKR1C3
F49: GOBP_ALPHA_AMINO_ACID_BIOSYNTHETIC_PROCESS | G49: Alpha Amino Acid Biosynthetic Process | H49: 0.10479574 | I49: 0.41486409 | J49: 0.18302394 | K49: -0.39213612 | L49: -1.3083725 | M49: 44 | N49: SEPHS1, PSAT1, GLS2, ASNS, MTHFD1, CTH, PSPH, SEPHS2, PYCR2, GOT2, PHGDH, ALDH18A1, PYCR1, ENOPH1, CAD, CBS, MTHFD2L, GOT1, MTAP, MRI1
F50: GOBP_ALPHA_AMINO_ACID_METABOLIC_PROCESS | G50: Alpha Amino Acid Metabolic Process | H50: 0.04091653 | I50: 0.26724491 | J50: 0.28785712 | K50: -0.33235902 | L50: -1.3344065 | M50: 130 | N50: AASS, SEPHS1, ATCAY, NAT8L, GLDC, GPT2, PIPOX, PSAT1, GLS2, IDO1, CRYM, ASNS, RIMKLA, ACAD8, MTHFD1, NMNAT2, AUH, NOS2, CTH, PSPH, SEPHS2, PYCR2, AFMID, GOT2, GCDH, UCP2, IVD, HIBCH, PHGDH, GCLC, ALDH18A1, CARNMT1, ACADSB, BCAT2, AZIN1, PYCR1, ENOPH1
F51: GOBP_ALPHA_BETA_T_CELL_ACTIVATION | G51: Alpha Beta T Cell Activation | H51: 0.83442623 | I51: 0.92979736 | J51: 0.044864511 | K51: -0.20931929 | L51: -0.83074276 | M51: 118 | N51: LCK, ZBTB7B, MAPK8IP1, MYC, SOCS1, STAT3, SEMA4A, DOCK2, ABCC1, JAK1, PRKCZ, TOX, CD83, CD55, FOXP1, CEBPB, JAK3, ICOSLG, SPN, SOCS3, ADA, RELB, CBLB, OPA1, ZC3H12A, ITPKB, MEN1, STAT5A, IRF1, ELF4, RIPK2
F52: GOBP_ALPHA_BETA_T_CELL_DIFFERENTIATION | G52: Alpha Beta T Cell Differentiation | H52: 0.89826303 | I52: 0.96377367 | J52: 0.060640401 | K52: 0.20132506 | L52: 0.8080528 | M52: 93 | N52: TMEM98, LEF1, PIK3R1, CBFB, IL6ST, RORA, CTSL, GLI3, AP3B1, ENTPD7, MALT1, ATF2, RC3H2, ANXA1
F53: GOBP_ALPHA_BETA_T_CELL_PROLIFERATION | G53: Alpha Beta T Cell Proliferation | H53: 0.27746741 | I53: 0.61011781 | J53: 0.10925004 | K53: -0.40881735 | L53: -1.1617134 | M53: 20 | N53: ZBTB7B, MAPK8IP1, MYC, DOCK2, CD55, CBLB, IRF1, ELF4, RIPK2
F54: GOBP_ALTERNATIVE_MRNA_SPLICING_VIA_SPLICEOSOME | G54: Alternative Mrna Splicing Via Spliceosome | H54: 0.22222222 | I54: 0.54935602 | J54: 0.11724972 | K54: -0.31330964 | L54: -1.1497282 | M54: 71 | N54: ESRP2, RBPMS, RBM47, RBFOX3, CELF5, RBPMS2, KHDRBS3, NOVA2
F55: GOBP_AMEBOIDAL_TYPE_CELL_MIGRATION | G55: Ameboidal Type Cell Migration | H55: 0.078733755 | I55: 0.35673538 | J55: 0.28780513 | K55: 0.28108239 | L55: 1.2465589 | M55: 184 | N55: FBN2, CDH2, MMP2, GJA1, MCC, NRP1, WNT5A, ENPP2, SEMA4D, AKT1, GLIPR2, HAS2, PTPRG, AKAP12, ZEB2, GPC3, ARSB, GBX2, PPARD, APPL2, FN1, DAAM2, RIC8A, CD63, TGFBR1, SEMA7A, BMP4, MAP4K4, KANK2, CLASP2, ARID5B, ITGB1BP1, BMPR2, PHACTR4, SASH1
F56: GOBP_AMIDE_BIOSYNTHETIC_PROCESS | G56: Amide Biosynthetic Process | H56: 0.44102564 | I56: 0.72454212 | J56: 0.10027911 | K56: 0.23800343 | L56: 1.0046945 | M56: 124 | N56: PDK1, NANP, MGST2, HACD1, ST6GALNAC3, ACSS2, ELOVL1, ST8SIA2, SMPD1, ASS1, DEGS1, ST3GAL3, FASN, PPT1, ACLY, FH, ELOVL6, PRKCD, ORMDL1
F57: GOBP_AMIDE_METABOLIC_PROCESS | G57: Amide Metabolic Process | H57: 0.013771891 | I57: 0.14461174 | J57: 0.3807304 | K57: 0.28001945 | L57: 1.3105473 | M57: 318 | N57: PDK1, EPHA4, PCSK5, ROCK2, ABCG1, NANP, AADAT, MGST2, HACD1, LRP4, MVK, GSTO1, ST6GALNAC3, NAGK, BACE1, CLN6, EFNA1, HLCS, ACSF2, ACSS2, MVD, MME, ELOVL1, HMGCS1, PCSK7, ST8SIA2, GPAM, SMPD1, GALC, HSD17B4, HMGCR, PRCP, CTSL, CTSZ, ASS1, CTNS, DEGS1, ST3GAL3, SHMT1, LDLR, TMED10, FASN, DISP1, FAR1, CERK, PPT1, ACLY, NSMAF, GSTA4, ACOT1, NCSTN, FH, PRNP, ELOVL6, P4HB, SCARB2, IDE, PRKCD, NUDT19, ORMDL1, TM9SF2
F58: GOBP_AMIDE_TRANSPORT | G58: Amide Transport | H58: 0.10114192 | I58: 0.405704 | J58: 0.17821987 | K58: -0.28937659 | L58: -1.2027591 | M58: 177 | N58: TCF7L2, VSNL1, PDPN, BRSK2, GNAO1, FOXO1, TUNAR, CAMK2G, ADCY5, RAB3A, RIMS2, PIM3, ACVR2B, GNAZ, SLC8B1, SOX4, GAL, TM7SF3, IRS2, CPT1A, SLC38A5, MCU, ABCC1, NOS2, SLC13A3, PICK1, ABAT, SLC16A10, UCP2, RAPGEF3, STX4, BAIAP3, SLC25A39, TRPM4, PFKM, VGF, PTPRN, RAB11FIP5, ABCA2, NMU, MGST1, PCLO, SYT7, SLC27A1
F59: GOBP_AMINE_BIOSYNTHETIC_PROCESS | G59: Amine Biosynthetic Process | H59: 0.76970954 | I59: 0.89813196 | J59: 0.059476029 | K59: 0.2682663 | L59: 0.807586 | M59: 24 | N59: ODC1
... F83: GOBP_ANGIOGENESIS_INVOLVED_IN_WOUND_HEALING | G83: Angiogenesis Involved In Wound Healing | H83: 0.4371134 | I83: 0.72193492 | J83: 0.088094501 | K83: 0.34410942 | L83: 1.00665 | M83: 22 | N83: ADIPOR2, TNFAIP3, NPR2, SLC12A2, PRCP, B4GALT1, GATA2, KDR
A84: yes_final | B84: no_redundant | C84: =IF(L84>0,"eMPC-side","iPSC-side") -> eMPC-side | D84: cardiovascular and endocardial development | E84: =VLOOKUP(F84,collapsed1!A:J,10,FALSE) -> main | F84: GOBP_SEMI_LUNAR_VALVE_DEVELOPMENT | G84: Semi Lunar Valve Development | H84: 1.0506048e-05 | I84: 0.001429698 | J84: 0.59332548 | K84: 0.65687785 | L84: 2.1924666 | M84: 38 | N84: AXIN2, ROBO1, SNAI1, ROCK2, CDH11, EFNA1, BMP2, STRA6, ADAMTS19, NOTCH1, BMP4, SNAI2, EMILIN1, BMPR2
F85: GOBP_ANIMAL_ORGAN_MATURATION | G85: Animal Organ Maturation | H85: 0.099137931 | I85: 0.40054608 | J85: 0.20895503 | K85: 0.49484929 | L85: 1.3942421 | M85: 19 | N85: SEMA4D, BMP2, DCHS1, ALDH1A2, MBTPS2, EBP
F86: GOBP_ANIMAL_ORGAN_REGENERATION | G86: Animal Organ Regeneration | H86: 0.2887931 | I86: 0.61768322 | J86: 0.11623415 | K86: 0.34523744 | L86: 1.118476 | M86: 32 | N86: LPIN1, EZH2, PTCH1, NOTCH1, CCND1
F87: GOBP_ANOIKIS | G87: Anoikis | H87: 0.72978723 | I87: 0.87467343 | J87: 0.063219117 | K87: 0.26880353 | L87: 0.84307701 | M87: 28 | N87: PIK3R3, ITGA5, AKT1, NOTCH1, SNAI2, BRMS1, PIK3CA, MAP3K7, SRC
F88: GOBP_ANTERIOR_POSTERIOR_AXIS_SPECIFICATION | G88: Anterior Posterior Axis Specification | H88: 0.33688699 | I88: 0.64674082 | J88: 0.10552094 | K88: 0.33315002 | L88: 1.0721795 | M88: 31 | N88: WLS, WNT5A, TBX3, GPC3
A89: no_redundant_auto | B89: =VLOOKUP(G89,decisions1!A:B,2,FALSE) -> no_redundant | C89: =IF(L89>0,"eMPC-side","iPSC-side") -> eMPC-side | D89: cardiovascular and endocardial development | E89: =VLOOKUP(F89,collapsed1!A:J,10,FALSE) -> redundant | F89: GOBP_AORTIC_VALVE_MORPHOGENESIS | G89: Aortic Valve Morphogenesis | H89: 1.9423601e-05 | I89: 0.0019824213 | J89: 0.57561026 | K89: 0.68019267 | L89: 2.1890698 | M89: 31 | N89: AXIN2, ROBO1, SNAI1, ROCK2, CDH11, EFNA1, ADAMTS19, NOTCH1, BMP4, SNAI2, EMILIN1
F90: GOBP_ANTEROGRADE_AXONAL_TRANSPORT | G90: Anterograde Axonal Transport | H90: 0.15140845 | I90: 0.47129507 | J90: 0.14920754 | K90: -0.38388805 | L90: -1.2595237 | M90: 39 | N90: KIF1A, KIF21A, KIF5A, KIF1C, NETO1, TRIM46, MAP2, HAP1, HSPB1, FEZ1
F91: GOBP_ANTIGEN_PROCESSING_AND_PRESENTATION | G91: Antigen Processing And Presentation | H91: 0.30626058 | I91: 0.62908619 | J91: 0.097215081 | K91: -0.30980067 | L91: -1.0962446 | M91: 55 | N91: RAB3C, THBS1, UNC93B1, HLA-B, ABCC1, HLA-C, CTSH, RAB3B, PSME1, HLA-DPB1, MFSD6, RFTN1
F92: GOBP_ANTIGEN_PROCESSING_AND_PRESENTATION_OF_EXOGENOUS_ANTIGEN | G92: Antigen Processing And Presentation Of Exogenous Antigen | H92: 0.30113636 | I92: 0.6258135 | J92: 0.10512513 | K92: -0.39354378 | L92: -1.1312747 | M92: 21 | N92: UNC93B1, HLA-B, HLA-C, PSME1, HLA-DPB1, MFSD6
F93: GOBP_ANTIGEN_PROCESSING_AND_PRESENTATION_OF_EXOGENOUS_PEPTIDE_ANTIGEN | G93: Antigen Processing And Presentation Of Exogenous Peptide Antigen | H93: 0.05380334 | I93: 0.30603448 | J93: 0.26635066 | K93: -0.53929862 | L93: -1.4582853 | M93: 17 | N93: UNC93B1, HLA-B, HLA-C, HLA-DPB1, MFSD6
...

Sheet collapsed1
A1: pathway | B1: pathway_clean | C1: pval | D1: padj | E1: log2err | F1: ES | G1: NES | H1: size | I1: leadingEdge | J1: collapsed_status
A2: GOBP_ALCOHOL_METABOLIC_PROCESS | B2: Alcohol Metabolic Process | C2: 0.0021564555 | D2: 0.047548176 | E2: 0.4317077 | F2: 0.33561772 | G2: 1.5159304 | H2: 212 | I2: PCSK9, TTC39B, SOAT1, CYP51A1, ABCG1, QDPR, DAB2, GNAI1, MVK, IDI1, CLN6, LMF1, HSD17B7, BMP2, ACSS2, H6PD, MVD, NSDHL, PPARD, NUDT11, CES2, HMGCS1, NUDT10, LSS, SMPD1, LIMA1, IDH2, ALDH1A2, MBTPS2, NPC1, TSKU, HMGCR, HDLBP, INSIG1, DHCR24, EBP, INPP4A, LDLR, SGPP1, PRKACA, IMPA1, ABCA5, DHCR7, FKRP, ACLY, OCRL, PARK7, CYP27A1, CUBN, STARD4, SQLE, MSMO1, FDPS, PTH1R, CYP27C1, PNPLA4, KPNB1, COQ2, SULT1C4, AKR7A2, SC5D, PAQR3 | J2: main
A3: GOBP_ANIMAL_ORGAN_FORMATION | B3: Animal Organ Formation | C3: 0.0011022323 | D3: 0.032431446 | E3: 0.45505987 | F3: 0.5449802 | G3: 1.8147456 | H3: 37 | I3: AXIN2, ROBO1, FOXH1, WNT5A, BMP2, HOXA3, NOTCH1, EMP2, DKK1, GLI3, BMP4 | J3: redundant
A4: GOBP_ANTERIOR_POSTERIOR_PATTERN_SPECIFICATION | B4: Anterior Posterior Pattern Specification | C4: 3.9301429e-09 | D4: 2.2373374e-06 | E4: 0.7614608 | F4: 0.52976756 | G4: 2.2520977 | H4: 130 | I4: AXIN2, NKD1, PLXNA2, DLL3, HES6, WLS, MLLT3, PCSK5, FOXH1, WNT5A, HOXC4, MSX1, LFNG, HOXA5, LEF1, HOXB6, HOXB5, BHLHE40, BMP2, TBX3, ZEB2, GPC3, HOXB4, HIPK2, HOXA3, POFUT1, GBX2, NOTCH1, TSHZ1, HOXA9, HOXB8, HOXB7, HOXB3, HOXB9, HOXB2, ALDH1A2, FOXC1, DKK1, HOXC6, TGFBR1, GLI3, BMP4, POGLUT1 | J4: main
A5: GOBP_AORTIC_VALVE_MORPHOGENESIS | B5: Aortic Valve Morphogenesis | C5: 1.9423601e-05 | D5: 0.0019824213 | E5: 0.57561026 | F5: 0.68019267 | G5: 2.1890698 | H5: 31 | I5: AXIN2, ROBO1, SNAI1, ROCK2, CDH11, EFNA1, ADAMTS19, NOTCH1, BMP4, SNAI2, EMILIN1 | J5: redundant
A6: GOBP_ARGININE_METABOLIC_PROCESS | B6: Arginine Metabolic Process | C6: 0.00038326636 | D6: 0.014064583 | E6: 0.49849311 | F6: 0.71828548 | G6: 1.9536918 | H6: 16 | I6: SLC39A8, ODC1, DDAH1, OAT, ATP2B4, ASS1 | J6: main
A7: GOBP_ARTERY_DEVELOPMENT | B7: Artery Development | C7: 0.0022863695 | D7: 0.049452203 | E7: 0.4317077 | F7: 0.42247956 | G7: 1.6688065 | H7: 83 | I7: ROBO1, FOXH1, NRP1, ZMIZ1, MDK, EFEMP2, APLNR, STRA6, NOTCH1, SUFU, PKD2, FOXC1, DCTN5, ADAMTS9, TGFBR1, GLI3, BMP4, LDLR, MYLK, BMPR2, FOXF1, NFATC3 | J7: redundant
A8: GOBP_ARTERY_MORPHOGENESIS | B8: Artery Morphogenesis | C8: 0.00078928005 | D8: 0.025027074 | E8: 0.47727082 | F8: 0.49978089 | G8: 1.8100787 | H8: 54 | I8: FOXH1, NRP1, ZMIZ1, MDK, EFEMP2, STRA6, NOTCH1, PKD2, FOXC1, ADAMTS9, TGFBR1, BMP4, LDLR, MYLK, BMPR2, FOXF1, NFATC3 | J8: redundant
A9: GOBP_ATRIOVENTRICULAR_VALVE_DEVELOPMENT | B9: Atrioventricular Valve Development | C9: 0.00032724716 | D9: 0.012610516 | E9: 0.49849311 | F9: 0.66481746 | G9: 2.0013594 | H9: 24 | I9: AXIN2, EFNA1, APLNR, BMP2, ADAMTS19, NOTCH1, DCHS1 | J9: redundant
A10: GOBP_AXON_DEVELOPMENT | B10: Axon Development | C10: 0.0017438055 | D10: 0.043475334 | E10: 0.45505987 | F10: -0.32247645 | G10: -1.4532779 | H10: 338 | I10: DAG1, VASH2, GPM6B, RND2, CDH1, FGFR2, USP9X, BRSK2, COBL, CYFIP2, UCHL1, UNC5B, CELSR2, PTPRF, THY1, CXCL12, VASP, FGF13, NLGN3, DRAXIN, PTPRZ1, TNFRSF12A, MACF1, CELSR3, CNTN1, RTN4RL2, SEMA3F, KIF21A, SEMA6B, RAB3A, SEMA6A, OTX2, PAK1, BCL11A, EPHB1, STXBP1, ATP8A2, ERBB2, EPHB6, KIF5A, ARHGAP4, MATN2, APOE, NMNAT2, AUTS2, ANK3, DCLK1, MAP2K1, EMB, HMCN2, SEMA4A, SEMA5A, PARD6B, SEMA4B, B4GALT6, NFASC, TSPO, MAP1S, PLP1, PRICKLE1, NOVA2, CTTN, OLFM1, STK11, ETV1, SPP1, CD2AP, LYPLA2, LAMB2, RTN4R, JUN, SEMA6C, VCL, NRXN1, KIF13B, L1CAM, PLEKHG4, TRIM46, MAP2, LPAR3, APBB2, METRN, GLI2, NGFR, LMO4, LIMK1, NOTCH3, TWF2, ADGRB1, CTNNA1, NUMB, RAC3, FEZ1, PTPRJ, SHTN1, SIN3A, SMURF1 | J10: redundant
A11: GOBP_BEHAVIOR | B11: Behavior | C11: 0.0021250923 | D11: 0.047538023 | E11: 0.4317077 | F11: -0.3078786 | G11: -1.4017242 | H11: 390 | I11: GPR176, GABRB3, ITGA3, SHANK2, VLDLR, EIF2AK4, NRXN2, BRINP1, GNAO1, JPH4, UCHL1, GRIN2D, NLGN4X, P2RY1, FGF2, CXCL12, FGF13, KIT, NLGN3, MMP17, STRBP, ARRB2, TP53, SLC1A1, IDO1, PTPRZ1, ZFHX2, GATM, ADCY5, CNTN1, PRKAR1B, INSR, GNB1L, GNG7, STAT3, ATP8A2, JPH3, SLC1A3, GABRA5, PIANP, APOE, ITPR3, ATP1B2, ADM2, GAL, THBS1, KRAS, CPT1A, NLGN1, ARC, TSPO, PRKAR2B, ABCC1, ATP1A2, TMEM63B, NDRG4, NPAS1, ETV1, GPR37, DEAF1, ABAT, VPS13A, FIG4, NETO1, CALB1, ATP8A1, FADD, NPW, SLC18A2, NRXN1, UCK2, MTA1, SNCG, CEBPB, RAPGEF3, CIART, CNTNAP2, BAIAP3, CHRNB1, ADA, MFSD2A, EDNRB, GDF15, HPRT1, PBX3, OPN3, THBS4, FXR1, SDK1, TMOD1, APRT, EPHB2, MRAP2, SYT11, IGLON5, ABCA7, GIT1, BBS4, SEZ6L2 | J11: redundant
A12: GOBP_BIOLOGICAL_PROCESS_INVOLVED_IN_INTRASPECIES_INTERACTION_BETWEEN_ORGANISMS | B12: Biological Process Involved In Intraspecies Interaction Between Organisms | C12: 0.0017750546 | D12: 0.043919154 | E12: 0.45505987 | F12: -0.56175388 | G12: -1.7672877 | H12: 33 | I12: GABRB3, SHANK2, NRXN2, BRINP1, NLGN4X, NLGN3, GNB1L, PIANP, VPS13A, NRXN1, CNTNAP2 | J12: main
A13: GOBP_BONE_DEVELOPMENT | B13: Bone Development | C13: 3.8340195e-06 | D13: 0.00065904778 | E13: 0.61052688 | F13: 0.43330854 | G13: 1.8790714 | H13: 152 | I13: AXIN2, ASXL1, GJA1, SEMA4D, FBN1, MSX1, AMER1, MMP14, ATP6AP1, HAS2, BMP2, HOXB4, ANXA2, SMAD1, TRIP11, P3H1, DCHS1, INPPL1, SLC38A10, NAB2, FOXC1, MBTPS2, NPR2, TSKU, INSIG1, EBP, GLI3, BMP4, PPIB, SBDS, COL13A1, MMP16, PRKG1, COL6A1, SMAD5, BMPR2, FREM1, GGCX, MSX2, GNAS, KDR, ATF2, RAB23, TULP3, SH3PXD2B | J13: redundant
... A152: GOBP_VESICLE_MEDIATED_TRANSPORT_IN_SYNAPSE | B152: Vesicle Mediated Transport In Synapse | C152: 1.6854627e-05 | D152: 0.0018349071 | E152: 0.57561026 | F152: -0.42145111 | G152: -1.7682016 | H152: 187 | I152: UNC13A, RIMS3, BRSK2, SYT2, SYT13, SYP, P2RY1, GRIK5, NLGN3, IQSEC2, SYN1, RIMS4, PRKCB, RAB5A, PRKAR1B, RAB3A, RIMS2, CACNA1B, STXBP1, DNAJC6, SYNGR3, PREPL, CADPS2, SNPH, PPFIA3, UNC13B, PACSIN1, OSBPL2, NLGN1, ARC, MX2, EPS15L1, EFR3A, SYN3, PRRT2, STX1B, STON1, ATP6V1A, ATP8A1, BSN, RAB3B, SUSD4, SLC18A2, NRXN1, SNCG, SYN2, NUMB, SYT17, MX1, SYT11, EPS15, GIT1, VAMP2, ATP6V1C1, SLC4A8, CBLB, SLC17A5, PCLO, SYT7, PLS3, SNAP47, SYNJ2, ATP6V1B2, ITSN1, AP2A1, STXBP2, DVL1, GRIPAP1, TPRG1L, CALM2, OPHN1, RAC1 | J152: redundant

Sheet decisions1
A1: pathway_clean | B1: include_apriori
A2: Anterior Posterior Pattern Specification | B2: yes_apriori
A3: Heart Valve Morphogenesis | B3: no_redundant
A4: Semi Lunar Valve Development | B4: yes_apriori
A5: Aortic Valve Morphogenesis | B5: no_redundant
A6: Cholesterol Biosynthetic Process Via Desmosterol | B6: no_biology
A7: Endocardial Cushion Formation | B7: no_redundant
A8: Endocardial Cushion Morphogenesis | B8: no_redundant
A9: Heart Formation | B9: no_redundant
A10: Mesenchyme Morphogenesis | B10: no_redundant
A11: Heart Valve Development | B11: no_redundant
A12: Sterol Metabolic Process | B12: no_biology
... A152: Synaptic Vesicle Exocytosis | B152: no_biology

Sheet EC_vs_eMPC
A1: Include in signature? | B1: include_apriori | C1: Stage-associated side of contrast (auto from NES sign) | D1: Biological category | E1: Redundancy | F1: pathway | G1: pathway_clean | H1: pval | I1: padj | J1: log2err | K1: ES | L1: NES | M1: size | N1: leadingEdge
F2: GOBP_2_OXOGLUTARATE_METABOLIC_PROCESS | G2: 2 Oxoglutarate Metabolic Process | H2: 0.11851852 | I2: 0.22323038 | J2: 0.20429476 | K2: -0.49703922 | L2: -1.3914651 | M2: 15 | N2: GPT2, IDH1, AADAT, L2HGDH
F3: GOBP_3_UTR_MEDIATED_MRNA_DESTABILIZATION | G3: 3 Utr Mediated Mrna Destabilization | H3: 0.15841584 | I3: 0.27505908 | J3: 0.17520405 | K3: -0.43038926 | L3: -1.2855649 | M3: 19 | N3: TRIM71, HNRNPD, KHSRP, DHX36, TARDBP
F4: GOBP_3_UTR_MEDIATED_MRNA_STABILIZATION | G4: 3 Utr Mediated Mrna Stabilization | H4: 0.20537897 | I4: 0.32956049 | J4: 0.15114876 | K4: -0.40486199 | L4: -1.2257758 | M4: 20 | N4: HNRNPC, METTL16, HNRNPA0, RBM38, TARDBP, ELAVL1, RBM10
F5: GOBP_ACETYL_COA_BIOSYNTHETIC_PROCESS | G5: Acetyl Coa Biosynthetic Process | H5: 0.54457831 | I5: 0.650546 | J5: 0.084555744 | K5: -0.29734519 | L5: -0.91608513 | M5: 21 | N5: PDK1, ACLY
A6: yes_final | B6: =VLOOKUP(F6,decisions2!A:B,2,FALSE) -> yes_apriori | C6: =IF(L6>0,"EC-side","eMPC-side") -> EC-side | D6: angiogenesis / vasculogenesis | E6: =VLOOKUP(F6,collapsed2!A:J,10,FALSE) -> main | F6: GOBP_ENDOTHELIAL_CELL_MIGRATION | G6: Endothelial Cell Migration | H6: 1.0566802e-17 | I6: 1.8163777e-15 | J6: 1.0864405 | K6: 0.5763941 | L6: 2.565904 | M6: 174 | N6: THBS1, TGFB1, VASH1, EFNB2, PLXND1, ITGB1, RHOB, ANXA1, TGFB1I1, ADAMTS9, EFNA1, SPARC, KDR, HDAC7, TMSB4X, GADD45A, HSPB1, RRAS, NRP1, FOXP1, FSTL1, FLT4, ACVRL1, LGALS8, BCAR1, CDH13, ETS1, SEMA5A, TGFBR3, PLK2, LOXL2, GATA2, TEK, EPHB4, MYH9, TBXA2R, PIK3CG, GPX1, GATA3, PIK3CA, CD40, LGMN, GIPC1, SP100, GRN, EHD4, CEACAM1, SASH1, NRP2, ATP2B4, CORO1B, PLEKHG5, ITGB1BP1, STARD13, PTPRM, FN1, RAB13, PXN, ZNF580, CARD10, TNFSF12, ADGRA2, SOX18, PDGFB, VEGFC, DLL4, PPARG, MMRN2, HMOX1, CIB1, NFE2L2, CLEC14A, EGF, PRCP, BMPER, CDH5, MET, RIN2, STC1, PTP4A3, RHOA
F7: GOBP_ACIDIC_AMINO_ACID_TRANSPORT | G7: Acidic Amino Acid Transport | H7: 0.18120805 | I7: 0.30179781 | J7: 0.13145761 | K7: 0.35976437 | L7: 1.2432845 | M7: 40 | N7: ITGB1, SLC1A4, GIPC1, SNCA, ARL6IP5, PRAF2, TTYH3, PSEN1, SLC7A11, DTNBP1, STXBP1, SLC38A2, SLC25A12, LRRC8C, NPY5R
F8: GOBP_ACROSOME_ASSEMBLY | G8: Acrosome Assembly | H8: 0.46419753 | I8: 0.58109204 | J8: 0.094975153 | K8: -0.36041347 | L8: -1.0089803 | M8: 15 | N8: CEP78, CCDC136, PLA2G3, CEP70
F9: GOBP_ACROSOME_REACTION | G9: Acrosome Reaction | H9: 0.60301508 | I9: 0.69937757 | J9: 0.081302735 | K9: -0.31615729 | L9: -0.90278815 | M9: 16 | N9: HVCN1, SYT6, TRIM36, CACNA1H
F10: GOBP_ACTIN_FILAMENT_BASED_MOVEMENT | G10: Actin Filament Based Movement | H10: 0.16975309 | I10: 0.28830659 | J10: 0.13010563 | K10: 0.30053834 | L10: 1.198357 | M10: 87 | N10: MYO1C, PARVA, MYO6, SUN2, GSN, TRPM4, MYH9, PIK3CA, MYL6, ACTA2, TPM1, WIPF1, ACTN4, SHTN1, MYO5A, FRMD6, MYO9B, STC1, WASF2, GPD1L, SRI, PDE4D, QKI, PDE4B
A11: yes_final | B11: =VLOOKUP(F11,decisions2!A:B,2,FALSE) -> no_redundant | C11: =IF(L11>0,"EC-side","eMPC-side") -> EC-side | D11: angiogenesis / vasculogenesis | E11: =VLOOKUP(F11,collapsed2!A:J,10,FALSE) -> main | F11: GOBP_SPROUTING_ANGIOGENESIS | G11: Sprouting Angiogenesis | H11: 4.260018e-12 | I11: 3.3126711e-10 | J11: 0.88707499 | K11: 0.59045206 | L11: 2.45003 | M11: 107 | N11: THBS1, TGFB1, FLT1, EFNB2, ITGB1, JAK1, TSPAN18, ANXA1, PARVA, ADAMTS9, ITGA5, NRARP, RNF213, KDR, HDAC7, NRP1, FLT4, ACVRL1, CDH13, SEMA5A, TGFBR3, PLK2, LOXL2, TGM2, GATA2, TEK, ENG, EPHB4, TBXA2R, EHD4, CEACAM1, ITGB1BP1, ADGRG6, STARD13, RECK, RAMP2, CARD10, PGF, ADGRA2, VEGFC, DLL4, EPN2, NGFR, MMRN2, HMOX1, CIB1, CLEC14A, CREB3L1, BMPER, CDH5, RHOA
A12: no_redundant_auto | B12: =VLOOKUP(F12,decisions2!A:B,2,FALSE) -> no_redundant | C12: =IF(L12>0,"EC-side","eMPC-side") -> EC-side | D12: angiogenesis / vasculogenesis | E12: =VLOOKUP(F12,collapsed2!A:J,10,FALSE) -> redundant | F12: GOBP_REGULATION_OF_ENDOTHELIAL_CELL_MIGRATION | G12: Regulation Of Endothelial Cell Migration | H12: 1.8228225e-12 | I12: 1.566668e-10 | J12: 0.89867123 | K12: 0.55917154 | L12: 2.3937596 | M12: 135 | N12: THBS1, TGFB1, VASH1, RHOB, ANXA1, ADAMTS9, EFNA1, SPARC, KDR, HDAC7, TMSB4X, GADD45A, HSPB1, RRAS, NRP1, FOXP1, FLT4, ACVRL1, BCAR1, ETS1, SEMA5A, TGFBR3, PLK2, GATA2, TEK, TBXA2R, PIK3CG, GATA3, CD40, LGMN, SP100, GRN, CEACAM1, SASH1, NRP2, ATP2B4, ITGB1BP1, STARD13, PTPRM, ZNF580, CARD10, ADGRA2, PDGFB, VEGFC, DLL4, PPARG, MMRN2, HMOX1, CIB1, NFE2L2, EGF, PRCP, BMPER, MET, RIN2, STC1, RHOA, NOS3, FGF2, MAPK14, MECP2, MMRN1, MAP2K3, MEF2C, ADAM17, PRKCA, NOTCH1, EDN1, PRKD2, NR2F2, PIK3CD
A13: yes_final | B13: =VLOOKUP(F13,decisions2!A:B,2,FALSE) -> yes_apriori | C13: =IF(L13>0,"EC-side","eMPC-side") -> EC-side | D13: angiogenesis / vasculogenesis | E13: =VLOOKUP(F13,collapsed2!A:J,10,FALSE) -> main | F13: GOBP_BLOOD_VESSEL_MORPHOGENESIS | G13: Blood Vessel Morphogenesis | H13: 3.9809644e-23 | I13: 1.4446477e-20 | J13: 1.2462328 | K13: 0.48332826 | L13: 2.3771477 | M13: 452 | N13: COL4A1, THBS1, COL4A2, TGFB1, VASH1, FLT1, UNC5B, EFNB2, PLXND1, ITGB1, ANXA2, RHOB, JAK1, TSPAN18, ANXA1, PARVA, HS6ST1, ERAP1, ADAMTS9, ELK3, EFNA1, SAT1, THSD7A, ITGA5, NRARP, SPARC, BCAM, TGFBR2, MEIS1, RNF213, KDR, BMPR2, HDAC7, JUN, GADD45A, JAG1, HSPB1, EGFL7, STAT3, RRAS, PTPRB, NRP1, FLT4, JUNB, MCAM, ACVRL1, TIE1, HSPG2, FZD8, CDH13, MYO1E, FZD4, ETS1, TNFAIP2, SEMA5A, TGFBR3, PLK2, LOXL2, TGM2, SHC1, GATA2, EFEMP2, TEK, HEG1, ENG, EPHB4, PXDN, MYH9, TBXA2R, PIK3CG, GPX1, PIK3CA, RELA, CD40, JAM3, MMP14, COL3A1, SP100, COL18A1, GRN, EHD4, EPAS1, CEACAM1, SASH1, TMEM100, B4GALT1, NRP2, FOXO4, BAX, ATP2B4, PLEKHG5, ADAM15, ANPEP, ITGB1BP1, RUNX1, ADGRG6, STARD13, PTPRM, NPR1, RASIP1, RECK, ITGAV, HEY1, FN1, RAMP2, FYN, CARD10, TNFSF12, NEDD4, MYDGF, PGF, ADGRA2, SOX18, HEY2, PDGFB, S1PR1, BTG1, ROBO4, VEGFC, DLL4, EPN2, SOX17, NGFR, PPARG, GPR4, RAPGEF2, EGLN1, ZFPM2, MMRN2, HMOX1, CIB1, HIPK2, SLC12A6, STAB1, NFE2L2, CLEC14A, EGF, POFUT1, PRCP, HES1, SULF1, CD47, CREB3L1, PDGFA, STIM1, BMPER, SPHK1, CDH5, RIN2, ANGPTL4, RAP1A, PRDM1, RHOA, WASF2, FKBP10, HHEX, MYLK, TGFBI, NOS3, ADM, CASP8, NPR3, FGF2, TAL1, ESM1, TNFRSF12A, MAPK14, PDGFRB, QKI, PML, ADGRF5, CD93, NINJ1, TJP1, NOTCH4, CCM2, MECP2, ECM1, FMNL3, MMRN1, RAPGEF3, SHB, CALCRL, TYMP, SEC24B, HPSE, PRKCA, NOTCH1, EDN1, IGFBP7, ID1, PPP1R16B, PRKD2, COL15A1, KLF2, NR2F2, DAG1, MICALL1, PIK3CD, NAGLU, CSPG4, CCL2, CLDN5, LEPR, ECSCR, ADGRG1, EMILIN2, VPS4B, EMILIN1, VAV3, FOXC2, SERPINE1, ANGPT2
A14: no_redundant_auto | B14: =VLOOKUP(F14,decisions2!A:B,2,FALSE) -> no_redundant | C14: =IF(L14>0,"EC-side","eMPC-side") -> EC-side | D14: angiogenesis / vasculogenesis | E14: =VLOOKUP(F14,collapsed2!A:J,10,FALSE) -> redundant | F14: GOBP_POSITIVE_REGULATION_OF_ENDOTHELIAL_CELL_MIGRATION | G14: Positive Regulation Of Endothelial Cell Migration | H14: 8.8233887e-11 | I14: 5.4372052e-09 | J14: 0.83908894 | K14: 0.59389344 | L14: 2.3723218 | M14: 88 | N14: THBS1, TGFB1, RHOB, ANXA1, SPARC, KDR, HDAC7, TMSB4X, HSPB1, RRAS, NRP1, FOXP1, FLT4, BCAR1, ETS1, SEMA5A, TGFBR3, PLK2, GATA2, TEK, PIK3CG, GATA3, CD40, LGMN, GRN, SASH1, NRP2, ITGB1BP1, ZNF580, ADGRA2, PDGFB, VEGFC, HMOX1, CIB1, NFE2L2, EGF, MET, RIN2, NOS3, FGF2, MAPK14
F15: GOBP_ACTIN_MEDIATED_CELL_CONTRACTION | G15: Actin Mediated Cell Contraction | H15: 0.73427673 | I15: 0.80474758 | J15: 0.04879897 | K15: 0.22331861 | L15: 0.85703868 | M15: 71 | N15: PARVA, GSN, TRPM4, MYH9, PIK3CA, MYL6, ACTA2, TPM1, SHTN1, FRMD6, STC1, GPD1L, SRI, PDE4D, QKI, PDE4B
F16: GOBP_ACTIN_NUCLEATION | G16: Actin Nucleation | H16: 0.022403116 | I16: 0.062805645 | J16: 0.35248786 | K16: 0.44286457 | L16: 1.5149382 | M16: 38 | N16: ARPC1B, GSN, HIP1R, SPIRE1, CORO1B, ARPC3, ARPC5, WHAMM, ACTR2, FCHSD2, ARPC2, WASF2, ARPIN, ACTR3, BRK1, ARPC4, ARPC1A, PICK1, GMFG, ARF1
A17: no_redundant_auto | B17: =VLOOKUP(F17,decisions2!A:B,2,FALSE) -> yes_apriori | C17: =IF(L17>0,"EC-side","eMPC-side") -> EC-side | D17: hemostasis / coagulation | E17: =VLOOKUP(F17,collapsed2!A:J,10,FALSE) -> redundant | F17: GOBP_HEMOSTASIS | G17: Hemostasis | H17: 5.2235352e-13 | I17: 5.3312706e-11 | J17: 0.921426 | K17: 0.54276522 | L17: 2.3716343 | M17: 154 | N17: THBS1, F2R, CSRP1, ANXA2, TSPAN18, TFPI, IL6ST, TLN1, HSPB1, TSPAN9, CD59, CD9, FZD6, RASA3, DGKA, MYL12A, SH2B3, MYH9, TBXA2R, PIK3CG, PIK3CA, CD40, PEAR1, DGKH, PLAUR, COL3A1, AXL, VWF, PROS1, CEACAM1, P2RY1, ITGA2, ANXA5, PROCR, FN1, MERTK, PLAU, PDGFB, PRRG1, F2RL2, ITPR3, GNA12, THBD, DGKZ, NFE2L2, IL6R, PDGFA, ANGPTL4, TLR4, NOS3, SLC7A11, DTNBP1, STXBP1, MAPK14, SERPING1, SELP, GGCX, ACTN1, VCL, PLSCR1, MMRN1, C1GALT1C1, F11R, FLI1, HPSE, PRKCA, BLOC1S3, EDN1, PLCG2, DGKE, HPS5, RAB27A, STXBP3, ADGRG1, PAFAH2, ST3GAL4, EMILIN2, EMILIN1, VAV3, SERPINE1, ANGPT2, ACTB, CAV1, FIBP
F18: GOBP_ACTION_POTENTIAL | G18: Action Potential | H18: 0.6 | I18: 0.69687055 | J18: 0.085535695 | K18: -0.21905395 | L18: -0.94153835 | M18: 78 | N18: KCNG1, NUP155, CXADR, DSP, DLG1, FGF13, DSG2, GJC1, KCNH2, KCNQ2, MTOR, CLCN2, ATP1A2, NEDD4L
F19: GOBP_ACTIVATED_T_CELL_PROLIFERATION | G19: Activated T Cell Proliferation | H19: 0.038466529 | I19: 0.095537401 | J19: 0.32177592 | K19: 0.49750892 | L19: 1.5226454 | M19: 24 | N19: PRKAR1A, LRRC32, IGFBP2, FYN, PPP3CA, BTN3A1, IGF2, PRNP, LGALS9, TNFSF9, ICOSLG, FADD, IDO1, STAT5A, LAPTM5
F20: GOBP_ACTIVATION_OF_GTPASE_ACTIVITY | G20: Activation Of Gtpase Activity | H20: 0.8718593 | I20: 0.90931899 | J20: 0.062661823 | K20: -0.23338486 | L20: -0.66643121 | M20: 16 | N20: SIPA1L1, ECT2
A21: yes_final | B21: yes_apriori | C21: =IF(L21>0,"EC-side","eMPC-side") -> EC-side | D21: endothelial specification | E21: =VLOOKUP(F21,collapsed2!A:J,10,FALSE) -> main | F21: GOBP_ENDOTHELIUM_DEVELOPMENT | G21: Endothelium Development | H21: 1.6908121e-10 | I21: 9.2036539e-09 | J21: 0.8266573 | K21: 0.56574821 | L21: 2.3565492 | M21: 112 | N21: RHOB, KDR, TNFRSF1A, BMPR2, JAG1, LIPA, RAP1B, NRP1, FOXP1, FSTL1, ACVRL1, TIE1, FZD4, PLOD3, HEG1, BMP6, GPX1, RAB1B, COL18A1, GSTM3, EZR, CEACAM1, TMEM100, ICAM1, MYADM, MSN, STARD13, TJP2, ZDHHC21, HEY1, ZEB1, SOX18, HEY2, S1PR1, ADAMTS12, BTG1, ROBO4, DLL4, SOX17, RAPGEF2, MYD88, CDH5, MET, STC1, RAP1A, RHOA, RAB1A, ADD1, PDE4D, TJP1, NOTCH4, CCM2, VCL, EDF1, RAPGEF3, F11R, HPSE, NOTCH1, EDN1, ID1, PPP1R16B, PRKD2, NR2F2, NAGLU, RDX, CLDN5, FOXC2, KDM6B, APOLD1, RAPGEF1
A22: yes_final | B22: =VLOOKUP(F22,decisions2!A:B,2,FALSE) -> no_redundant | C22: =IF(L22>0,"EC-side","eMPC-side") -> EC-side | D22: wound healing and tissue repair | E22: =VLOOKUP(F22,collapsed2!A:J,10,FALSE) -> main | F22: GOBP_WOUND_HEALING | G22: Wound Healing | H22: 3.577495e-16 | I22: 5.0800429e-14 | J22: 1.0376962 | K22: 0.49684033 | L22: 2.34947 | M22: 286 | N22: THBS1, F2R, TGFB1, AHNAK, CSRP1, RHOC, ITGB1, ANXA2, ANXA1, CDKN1A, CD151, ELK3, MYOF, ITGA5, TFPI, KDR, IL6ST, TLN1, C6orf89, HSPB1, TSPAN9, CD59, CD9, FZD6, RASA3, MCAM, ACVRL1, CD44, DGKA, PLEC, GATA2, MYL12A, SH2B3, ENG, SMPD1, MYH9, TBXA2R, PIK3CG, GPX1, PIK3CA, CD40, CADM4, PEAR1, DGKH, PLAUR, COL3A1, AXL, CD109, VWF, PROS1, TIMP1, CEACAM1, P2RY1, SYTL4, MACF1, B4GALT1, SYT11, ITGA2, PRKCE, ANXA5, PROCR, CORO1B, CASP7, PTEN, SMAD3, HBEGF, PPARA, ITGAV, FN1, MERTK, CHMP6, TPM1, PPP3CA, PLAU, PDGFB, DST, PPARG, GPR4, PRRG1, HMOX1, FERMT2, F2RL2, ITPR3, GNA12, THBD, DGKZ, NFE2L2, IL6R, PRCP, PDGFA, CHMP2A, ANGPTL4, S100A10, RHOA, FKBP10, MYLK, TLR4, NOS3, OCLN, SLC7A11, FGF2, DTNBP1, TNFRSF12A, STXBP1, MAPK14, CHMP1B, SERPING1, SELP, GGCX, CHMP4B, ACTN1, VCL, EXT1, PLSCR1, MMRN1, CHMP1A, C1GALT1C1, F11R, ADAM17, HPSE, CRK, PRKCA, BLOC1S3, EDN1, PLCG2, DGKE, DAG1, HPS5, RAB27A, STXBP3, ADGRG1, PAFAH2, ST3GAL4, EMILIN2, VPS4B, EMILIN1, VAV3, FOXC2, SERPINE1, ANGPT2
A23: no_biology | B23: =VLOOKUP(F23,decisions2!A:B,2,FALSE) -> no_biology | C23: =IF(L23>0,"EC-side","eMPC-side") -> EC-side | D23: other | E23: =VLOOKUP(F23,collapsed2!A:J,10,FALSE) -> main | F23: GOBP_VACUOLE_ORGANIZATION | G23: Vacuole Organization | H23: 7.86384e-14 | I23: 8.5611005e-12 | J23: 0.95454163 | K23: 0.5082732 | L23: 2.3258614 | M23: 211 | N23: ANXA2, RALB, ATP6AP1, LIPA, LAMP2, WIPI1, SCARB2, MBTPS1, TFE3, ABCA1, HEXB, TCIRG1, TPP1, TMEM165, FEZ2, WDR45, STX12, RAB1B, PIK3C2B, GRN, MAP1LC3A, BAG3, TP53INP1, GNPTAB, LYST, SH3GLB1, PIP4K2A, LAMP1, CTSD, AKTIP, RAB7A, FEZ1, CLN5, TP53INP2, SRPX, CHMP6, OSBPL10, AP5Z1, TMEM63A, SNAPIN, ATP6AP2, GABARAPL1, VPS11, RAB14, VPS35, PACS2, VIPAS39, MTM1, BECN1, CHMP2A, ATP6V1A, TFEB, SNX18, ATG4A, PSEN1, SNX7, RAB1A, SLC7A11, RAB5A, PIK3C3, PI4KB, HEXA, GUSB, CHMP1B, ATG7, HID1, LAMTOR1, VMP1, CHMP4B, TMEM175, PINK1, ATP6V1F, EXT1, SNX4, CHMP1A, HPS1, GABARAP, ATG16L2, AP5S1, VPS16, MFSD8, GABARAPL2, ATP6V1H, NAGLU, TREX1, VPS39, TMEM106B, RAB43, ACP2, TBC1D12, SNX30, VPS4B, ATP6V0A1, NAGPA, FIG4, ARSG
F24: GOBP_ACTIVIN_RECEPTOR_SIGNALING_PATHWAY | G24: Activin Receptor Signaling Pathway | H24: 0.45193929 | I24: 0.57144163 | J24: 0.075501529 | K24: 0.31132358 | L24: 1.0017532 | M24: 30 | N24: TGFBR2, BMPR2, ACVRL1, FKBP1A, SMAD6, SMAD3
A25: no_redundant_auto | B25: =VLOOKUP(F25,decisions2!A:B,2,FALSE) -> no_redundant | C25: =IF(L25>0,"EC-side","eMPC-side") -> EC-side | D25: angiogenesis / vasculogenesis | E25: =VLOOKUP(F25,collapsed2!A:J,10,FALSE) -> redundant | F25: GOBP_REGULATION_OF_VASCULATURE_DEVELOPMENT | G25: Regulation Of Vasculature Development | H25: 6.4779006e-13 | I25: 6.4111585e-11 | J25: 0.921426 | K25: 0.50551532 | L25: 2.3097648 | M25: 206 | N25: THBS1, COL4A2, TGFB1, VASH1, FLT1, PLXND1, ITGB1, RHOB, JAK1, TSPAN18, ERAP1, ADAMTS9, EFNA1, ITGA5, SPARC, TGFBR2, KDR, GADD45A, HSPB1, STAT3, RRAS, NRP1, ACVRL1, TIE1, HSPG2, ETS1, SEMA5A, PLK2, TGM2, SHC1, GATA2, TEK, ADAM10, ENG, TBXA2R, PIK3CG, RELA, CD40, SP100, GRN, CEACAM1, SASH1, FOXO4, ATP2B4, RUNX1, ADGRG6, STARD13, PTPRM, NPR1, RECK, RAMP2, FYN, TNFSF12, MYDGF, ADGRA2, BTG1, VEGFC, EPN2, PPARG, GPR4, EGLN1, HMOX1, HIPK2, STAB1, NFE2L2, SULF1, CREB3L1, STIM1, BMPER, SPHK1, CDH5, ANGPTL4, HHEX, NOS3, ADM, FGF2, TNFRSF12A, QKI, PML, NINJ1, TJP1, CCM2, MECP2, ECM1, RAPGEF3, HPSE, PRKCA, ID1, PPP1R16B, PRKD2, KLF2, PIK3CD, CLDN5, ECSCR, EMILIN2, EMILIN1, FOXC2, SERPINE1, ANGPT2
A26: yes_final | B26: =VLOOKUP(F26,decisions2!A:B,2,FALSE) -> no_redundant | C26: =IF(L26>0,"EC-side","eMPC-side") -> EC-side | D26: hemostasis / coagulation | E26: =VLOOKUP(F26,collapsed2!A:J,10,FALSE) -> main | F26: GOBP_REGULATION_OF_BODY_FLUID_LEVELS | G26: Regulation Of Body Fluid Levels | H26: 1.9851436e-13 | I26: 2.0914449e-11 | J26: 0.94363223 | K26: 0.4951044 | L26: 2.2910062 | M26: 236 | N26: THBS1, F2R, CSRP1, ANXA2, TSPAN18, PRKAR1A, TFPI, IL6ST, TLN1, HSPB1, TSPAN9, CD59, CD9, FZD6, RASA3, CYBA, ZBTB7B, DGKA, HEG1, MYL12A, SH2B3, VAMP3, MYH9, TBXA2R, PIK3CG, PRKAR2B, ADCY6, PIK3CA, EXT2, CD40, GNAI2, PEAR1, DGKH, VAMP2, PLAUR, COL3A1, ADA, AXL, ADCY9, VWF, PROS1, AFAP1, CEACAM1, P2RY1, INPP5K, ITGA2, PRKCE, ANXA5, PROCR, FOSL2, PPARA, NPR1, FN1, MERTK, PPP3CA, PLAU, PDGFB, COPA, PRRG1, PRKACA, F2RL2, ITPR3, NR1H2, GNA12, SLC29A1, THBD, DGKZ, NFE2L2, IL6R, PRKAR2A, PDGFA, ANGPTL4, ADCY7, TRAF3IP2, TLR4, ATP7B, NOS3, ADM, NPR3, HYAL2, SLC7A11, DTNBP1, STXBP1, MAPK14, SERPING1, SELP, GGCX, AKAP11, ACTN1, VCL, EXT1, PLSCR1, MMRN1, C1GALT1C1, F11R, FLI1, HPSE, PRKCA, BLOC1S3, EDN1, PLCG2, DGKE, ADCY4, HPS5, RAB27A, STXBP3, SOCS2, ADGRG1, PAFAH2, ST3GAL4, EMILIN2, EMILIN1, VAV3, SERPINE1, ANGPT2, ACTB, CAV1, NR1H3, FIBP
F27: GOBP_ACYLGLYCEROL_HOMEOSTASIS | G27: Acylglycerol Homeostasis | H27: 0.26506024 | I27: 0.39619531 | J27: 0.13010563 | K27: -0.3751899 | L27: -1.1559154 | M27: 21 | N27: APOE, SCARB1, APOC1, SIRT1, FUNDC2, SLC25A27, RORA, OSBPL11
F28: GOBP_ACYL_COA_BIOSYNTHETIC_PROCESS | G28: Acyl Coa Biosynthetic Process | H28: 0.036574704 | I28: 0.091675353 | J28: 0.32177592 | K28: -0.37163435 | L28: -1.4272276 | M28: 46 | N28: PDK1, FASN, ELOVL6, PPT1, ACLY, ELOVL7, HACD2, HACD1, GCDH, ACSL4, ACSL1, PDHX, DLAT, HSD17B12
A29: no_redundant_manual | B29: =VLOOKUP(F29,decisions2!A:B,2,FALSE) -> no_redundant | C29: =IF(L29>0,"EC-side","eMPC-side") -> EC-side | D29: wound healing and tissue repair | E29: =VLOOKUP(F29,collapsed2!A:J,10,FALSE) -> main | F29: GOBP_RESPONSE_TO_WOUNDING | G29: Response To Wounding | H29: 8.6669966e-18 | I29: 1.5725784e-15 | J29: 1.0864405 | K29: 0.46822156 | L29: 2.2707213 | M29: 374 | N29: THBS1, F2R, TGFB1, VASH1, AHNAK, CSRP1, RHOC, ITGB1, ANXA2, COMT, ANXA1, CDKN1A, LAMB2, CD151, ELK3, SULF2, MYOF, ITGA5, TFPI, KDR, IL6ST, TLN1, JUN, C6orf89, HSPB1, TSPO, STAT3, TSPAN9, CD59, NRP1, CD9, FZD6, RASA3, NR3C1, MCAM, ACVRL1, CD44, DGKA, PLEC, GATA2, MYL12A, SH2B3, ENG, SMPD1, MYH9, TBXA2R, PIK3CG, GPX1, PIK3CA, CD40, CADM4, PEAR1, DGKH, PLAUR, COL3A1, GRN, AXL, CD109, VWF, PROS1, TIMP1, CEACAM1, P2RY1, SYTL4, MACF1, B4GALT1, SYT11, RTCA, BAX, ITGA2, PRKCE, ANXA5, PROCR, CORO1B, CASP7, PTEN, SMAD3, HBEGF, PPARA, ITGAV, FN1, MERTK, CHMP6, NFIB, CTNNA1, TPM1, PPP3CA, ARF4, PLAU, PDGFB, DST, PPARG, GPR4, PRRG1, FOSL1, HMOX1, FERMT2, F2RL2, ITPR3, GNA12, THBD, DGKZ, NFE2L2, IL6R, PRCP, PDGFA, CHMP2A, ANGPTL4, S100A10, RHOA, FKBP10, NMNAT1, MYLK, TLR4, NFKBIZ, NOS3, OCLN, SLC7A11, INHBB, FGF2, DTNBP1, TNFRSF12A, STXBP1, MAPK14, CHMP1B, SERPING1, SELP, GGCX, CHMP4B, ACTN1, VCL, EXT1, PLSCR1, MMRN1, CHMP1A, C1GALT1C1, F11R, ADAM17, HPSE, CRK, PRKCA, BLOC1S3, EDN1, MATN2, PLCG2, DGKE, EXTL3, DAG1, MTR, IL1RL1, SARM1, NAGLU, ABHD2, HPS5, RAB27A, STXBP3, ADGRG1, PAFAH2, ST3GAL4, INPP5F, ZFP36, EMILIN2, VPS4B, EMILIN1, VAV3, FOXC2, IL33, SERPINE1, MAP1B, ANGPT2
A30: no_redundant_auto | B30: =VLOOKUP(F30,decisions2!A:B,2,FALSE) -> no_redundant | C30: =IF(L30>0,"EC-side","eMPC-side") -> EC-side | D30: angiogenesis / vasculogenesis | E30: =VLOOKUP(F30,collapsed2!A:J,10,FALSE) -> redundant | F30: GOBP_BLOOD_VESSEL_ENDOTHELIAL_CELL_MIGRATION | G30: Blood Vessel Endothelial Cell Migration | H30: 9.0398123e-09 | I30: 3.1746266e-07 | J30: 0.74773966 | K30: 0.55832916 | L30: 2.2664039 | M30: 97 | N30: THBS1, TGFB1, VASH1, EFNB2, ITGB1, ANXA1, EFNA1, KDR, HDAC7, TMSB4X, GADD45A, HSPB1, NRP1, ACVRL1, ETS1, TGFBR3, PLK2, GATA2, EPHB4, MYH9, TBXA2R, GPX1, CD40, EHD4, ATP2B4, ITGB1BP1, STARD13, CARD10, SOX18, PDGFB, VEGFC, DLL4, PPARG, MMRN2, HMOX1, CIB1, NFE2L2, CLEC14A, PRCP, CDH5, RHOA, NOS3, FGF2, MAPK14, MECP2, MMRN1, MAP2K3, MEF2C, ADAM17, PRKCA, NOTCH1, ID1, PRKD2
A31: yes_final | B31: yes_apriori | C31: =IF(L31>0,"EC-side","eMPC-side") -> EC-side | D31: extracellular matrix organization / remodelling | E31: =VLOOKUP(F31,collapsed2!A:J,10,FALSE) -> main | F31: GOBP_COLLAGEN_METABOLIC_PROCESS | G31: Collagen Metabolic Process | H31: 5.7800471e-08 | I31: 1.613473e-06 | J31: 0.71951283 | K31: 0.59828781 | L31: 2.2644553 | M31: 66 | N31: FURIN, F2R, TGFB1, ITGB1, CTSB, PLOD1, VIM, TNS2, PLOD3, CST3, CTSL, MMP14, COL1A1, RCN3, ITGA2, ADAMTS2, ADAM15, FOSL2, RUNX1, P3H4, P3H1, ERRFI1, MMP15, VIPAS39, IL6R, MMP9, CREB3L1, RAP1A, CYGB
F32: GOBP_ADAPTIVE_THERMOGENESIS | G32: Adaptive Thermogenesis | H32: 0.57185629 | I32: 0.67352421 | J32: 0.058098358 | K32: 0.22591299 | L32: 0.94325829 | M32: 115 | N32: TRPV2, CLSTN3, LIPA, STAT6, ZBTB7B, TFE3, DECR1, LNPEP, THRA, ARRDC3, EPAS1, PWWP2B, PCTP, RB1, IL4R, NR1H2, PLCL1, IGF1R, IP6K1, TLR4, NOVA2, NPR3, QKI, LAMA4, PPARGC1A, ADAM17, ACOT11, NOTCH1, ID1, IL18R1, KDM3A, CEBPB, LEPR, FOXC2, KDM6B, DYNC1H1, CAV1, NR1H3, ADIPOR1
A33: no_redundant_auto | B33: =VLOOKUP(F33,decisions2!A:B,2,FALSE) -> no_redundant | C33: =IF(L33>0,"EC-side","eMPC-side") -> EC-side | D33: cell adhesion and cell-matrix interaction | E33: =VLOOKUP(F33,collapsed2!A:J,10,FALSE) -> redundant | F33: GOBP_CELL_MATRIX_ADHESION | G33: Cell Matrix Adhesion | H33: 6.1035448e-11 | I33: 3.9868355e-09 | J33: 0.83908894 | K33: 0.50629654 | L33: 2.2507733 | M33: 170 | N33: THBS1, ITGA3, ITGB1, ANXA2, ADAMTS9, ITGA5, TSPAN11, BCAM, KDR, TLN1, ITGA1, JAG1, NID1, RRAS, NRP1, CTTN, ADAM9, CD63, CSF1, ACVRL1, DAPK3, CDH13, CD44, EFEMP2, TEK, TAOK2, SGCE, JAM3, UTRN, MMP14, DUSP3, COL3A1, PPM1F, MACF1, ITGA2, ADAM15, ITGB1BP1, PTEN, MINK1, SMAD3, LIMS1, NID2, RSU1, PEAK1, ITGAV, BST1, FN1, PLAU, ADAMTS12, ARHGEF7, MAP4K4, CIB1, FERMT2, WHAMM, ITGA8, PIK3R1, ITGA4, RIN2, S100A10, RHOA, PTPRA, ACER2, CFL1, L1CAM, STON1, THBS3, ACTN1, VCL
F34: GOBP_ADENYLATE_CYCLASE_INHIBITING_G_PROTEIN_COUPLED_RECEPTOR_SIGNALING_PATHWAY | G34: Adenylate Cyclase Inhibiting G Protein Coupled Receptor Signaling Pathway | H34: 0.069651741 | I34: 0.14887604 | J34: 0.21925035 | K34: 0.41920341 | L34: 1.4004228 | M34: 33 | N34: PSAP, APP, PALM, ADCY6, GNAI2, P2RY1, ADGRG6, S1PR1, PRKACA
A35: no_redundant_auto | B35: =VLOOKUP(F35,decisions2!A:B,2,FALSE) -> no_redundant | C35: =IF(L35>0,"EC-side","eMPC-side") -> EC-side | D35: endothelial specification | E35: =VLOOKUP(F35,collapsed2!A:J,10,FALSE) -> redundant | F35: GOBP_ENDOTHELIAL_CELL_DIFFERENTIATION | G35: Endothelial Cell Differentiation | H35: 7.9790001e-09 | I35: 2.8954905e-07 | J35: 0.74773966 | K35: 0.55632142 | L35: 2.247259 | M35: 94 | N35: KDR, TNFRSF1A, BMPR2, JAG1, LIPA, RAP1B, NRP1, FSTL1, ACVRL1, TIE1, FZD4, PLOD3, HEG1, BMP6, GPX1, RAB1B, COL18A1, GSTM3, EZR, CEACAM1, TMEM100, ICAM1, MYADM, MSN, TJP2, ZDHHC21, HEY1, ZEB1, SOX18, HEY2, S1PR1, BTG1, ROBO4, SOX17, RAPGEF2, MYD88, CDH5, MET, STC1, RAP1A, RAB1A, ADD1, PDE4D, TJP1, NOTCH4, CCM2, VCL, EDF1, RAPGEF3, F11R, HPSE, NOTCH1, ID1, PPP1R16B, NR2F2, RDX, CLDN5, KDM6B, APOLD1, RAPGEF1
F36: GOBP_ADHERENS_JUNCTION_ORGANIZATION | G36: Adherens Junction Organization | H36: 0.13057851 | I36: 0.23985907 | J36: 0.1563124 | K36: 0.36570371 | L36: 1.2924175 | M36: 43 | N36: EFNB2, CDH13, MTSS1, PLEC, ADAM10, NUMB, BMP6, JAM3, RAMP2, CDC42, FERMT2, KIFC3, CDH5, PAK2, ADD1, PIP5K1C, TJP1, VCL, CDHR3
F37: GOBP_ADIPOSE_TISSUE_DEVELOPMENT | G37: Adipose Tissue Development | H37: 0.19543974 | I37: 0.3189936 | J37: 0.12384217 | K37: 0.31740575 | L37: 1.1856477 | M37: 60 | N37: LIPA, CSF1, TRPM4, ARRDC3, PIK3CA, LPL, PRKAA1, FOSL2, ERRFI1, DYRK1B, PPARG, SPTLC2, PPARGC1A, CUL4B, VPS13B, ABHD15, FTO, ACAT1, ARID5B
F38: GOBP_ADRENAL_GLAND_DEVELOPMENT | G38: Adrenal Gland Development | H38: 0.33609272 | I38: 0.46811249 | J38: 0.090542895 | K38: 0.39446294 | L38: 1.093219 | M38: 16 | N38: DKK3, TSPO, NR3C1, SMAD3
A39: no_redundant_auto | B39: =VLOOKUP(F39,decisions2!A:B,2,FALSE) -> no_biology | C39: =IF(L39>0,"EC-side","eMPC-side") -> EC-side | D39: other | E39: =VLOOKUP(F39,collapsed2!A:J,10,FALSE) -> redundant | F39: GOBP_LYTIC_VACUOLE_ORGANIZATION | G39: Lytic Vacuole Organization | H39: 4.2461575e-09 | I39: 1.6125524e-07 | J39: 0.7614608 | K39: 0.5496493 | L39: 2.2470184 | M39: 100 | N39: ATP6AP1, LIPA, LAMP2, SCARB2, MBTPS1, TFE3, ABCA1, HEXB, TCIRG1, TPP1, TMEM165, GRN, GNPTAB, LYST, LAMP1, AKTIP, RAB7A, CLN5, SRPX, CHMP6, OSBPL10, AP5Z1, TMEM63A, SNAPIN, ATP6AP2, RAB14, VPS35, VIPAS39, BECN1, CHMP2A, ATP6V1A, TFEB, SLC7A11, PI4KB, HEXA, GUSB, CHMP1B, LAMTOR1, CHMP4B, TMEM175, ATP6V1F, CHMP1A, HPS1, AP5S1, MFSD8, ATP6V1H, NAGLU, TREX1, TMEM106B, ACP2, ATP6V0A1, NAGPA, ARSG, MYO7A, VPS18, LAPTM4A, HOOK3, CREG1
F40: GOBP_ADULT_BEHAVIOR | G40: Adult Behavior | H40: 0.41194969 | I40: 0.53772363 | J40: 0.076674687 | K40: 0.25898643 | L40: 1.0265926 | M40: 85 | N40: APP, ATXN1, SNCG, SNCA, CNP, SHANK3, PTEN, WDR47, PPARA, NCSTN, BTBD9, UCHL1, CLCN3, HIPK2, CTNS, CSTB, BBS2, SLC7A11, FGF2, HEXA, TUBA1A, MECP2, PBX3, TMOD1, ARCN1, PCDH17, PREX2, NAGLU, OXR1, HTRA2, INPP5F
...

Sheet collapsed2
A1: pathway | B1: pathway_clean | C1: pval | D1: padj | E1: log2err | F1: ES | G1: NES | H1: size | I1: leadingEdge | J1: collapsed_status
A2: GOBP_ACETYL_COA_METABOLIC_PROCESS | B2: Acetyl Coa Metabolic Process | C2: 0.0093046086 | D2: 0.03229421 | E2: 0.3807304 | F2: -0.45783186 | G2: -1.6414105 | H2: 35 | I2: PDK1, FASN, HMGCS1, ACLY, AADAT, HMGCR, AASS, MVD, GCDH, PDHX, DLAT | J2: redundant
A3: GOBP_ACTIN_FILAMENT_BUNDLE_ORGANIZATION | B3: Actin Filament Bundle Organization | C3: 0.0075084506 | D3: 0.027277642 | E3: 0.40701792 | F3: 0.34804734 | G3: 1.5032783 | H3: 139 | I3: RHOC, ITGB1, PARVA, NRP1, MTSS1, TNFAIP1, ARRB1, EZR, PPM1F, SPIRE1, SHANK3, INPP5K, RAB40B, CORO1B, CGNL1, ITGB1BP1, SHROOM1, SMAD3, LIMS1, SYNPO, PXN, CDC42, TPM1, S1PR1, LIMD2, SHROOM2, SORBS3, FERMT2, SHTN1, PARVB, PIK3R1, FHOD1, CD47, PAK2, PDLIM1, S100A10, PLS3, RHOA, WASF2, ARHGAP28, ADD1, ARHGEF15, CFL1, ARPIN, TJP1, ACTN1, RAPGEF3, F11R, TACR1, PFN1, LUZP1, ZEB2, LIMCH1, TESK1, CALD1, ZYX | J3: redundant
A4: GOBP_ACTIN_FILAMENT_DEPOLYMERIZATION | B4: Actin Filament Depolymerization | C4: 0.00457494 | D4: 0.01894348 | E4: 0.40701792 | F4: 0.47954837 | G4: 1.6955076 | H4: 44 | I4: PPP1R9B, SVIL, SPTBN1, GSN, SEMA5A, TMOD2, PIK3CA, SPTAN1, ADD3, TWF2, TWF1, WDR1, CFL2, ADD1, CFL1, TRIOBP, MICAL2, TMOD1, CAPZA2, DSTN, TMOD3, RDX | J4: redundant
A5: GOBP_ACTIN_FILAMENT_ORGANIZATION | B5: Actin Filament Organization | C5: 9.2230179e-09 | D5: 3.2045081e-07 | E5: 0.74773966 | F5: 0.3942085 | G5: 1.8948088 | H5: 342 | I5: TAGLN2, CDC42EP1, RHOC, MYO1C, ITGB1, RHOB, PARVA, MYO6, CDC42EP3, PPP1R9B, SVIL, TMSB4X, SPTBN1, ARPC1B, GSN, ARHGEF12, NRP1, CTTN, GAS2L1, BCAR1, MYO1E, MTSS1, SEMA5A, PLEC, VASP, TNFAIP1, TMOD2, RAC2, TMSB10, IQGAP1, PIK3CA, GIPC1, HIP1R, ARRB1, SSH1, EZR, PPM1F, SPIRE1, SHANK3, SH3KBP1, SPTAN1, INPP5K, CNN3, CAP1, MYADM, ADD3, RAB40B, PRKCE, TWF2, DIAPH2, CORO1B, CGNL1, ITGB1BP1, SHROOM1, TWF1, WDR1, ARHGAP18, SMAD3, LIMS1, ABI1, SYNPO, PXN, ARPC3, CDC42, TPM1, ESAM, S1PR1, CFL2, LIMD2, SHROOM4, ARPC5, SHROOM2, WIPF1, INF2, SORBS3, FERMT2, SHTN1, MYO5A, RHOG, WHAMM, RICTOR, ACTR2, SAMD14, PARVB, PIK3R1, SH3BP4, FCHSD2, FHOD1, SSH2, TPM4, CD47, ARPC2, FCHSD1, PAK2, PDLIM1, S100A10, PLS3, RHOA, WASF2, TPM2, ARHGAP28, CDC42EP2, MICALL2, ADD1, ARHGEF2, RND1, RND3, ARHGEF15, CFL1, TRIOBP, RUFY3, ARPIN, MICAL2, TJP1, ACTN1, TMOD1, ACTR3, RAPGEF3, CAPZA2, F11R, DSTN, SNX9, BRK1, CYFIP2, NCK1, TACR1, PFN1 | J5: main
A6: GOBP_ACTIN_FILAMENT_POLYMERIZATION | B6: Actin Filament Polymerization | C6: 0.00014578363 | D6: 0.0012399202 | E6: 0.51884808 | F6: 0.42378588 | G6: 1.7640488 | H6: 111 | I6: CDC42EP1, CDC42EP3, SVIL, TMSB4X, SPTBN1, GSN, CTTN, VASP, TMOD2, HIP1R, SSH1, SPTAN1, MYADM, ADD3, PRKCE, TWF2, DIAPH2, TWF1, ARHGAP18, ARPC3, ESAM, ARPC5, INF2, RICTOR, FCHSD2, SSH2, ARPC2, FCHSD1, ARHGAP28, CDC42EP2, MICALL2, ADD1, CFL1, TRIOBP, TMOD1, CAPZA2, SNX9, CYFIP2, NCK1, PFN1, ARPC4, TMOD3 | J6: redundant
A7: GOBP_ACTIN_POLYMERIZATION_OR_DEPOLYMERIZATION | B7: Actin Polymerization Or Depolymerization | C7: 7.3702175e-05 | D7: 0.00070383422 | E7: 0.5384341 | F7: 0.41981996 | G7: 1.7958153 | H7: 134 | I7: CDC42EP1, CDC42EP3, PPP1R9B, SVIL, TMSB4X, SPTBN1, GSN, CTTN, SEMA5A, VASP, TMOD2, PIK3CA, HIP1R, SSH1, SPTAN1, MYADM, ADD3, PRKCE, TWF2, DIAPH2, TWF1, WDR1, ARHGAP18, ABI1, ARPC3, ESAM, CFL2, ARPC5, WIPF1, INF2, RICTOR, FCHSD2, SSH2, ARPC2, FCHSD1, ARHGAP28, CDC42EP2, MICALL2, ADD1, CFL1, TRIOBP, MICAL2, TMOD1, CAPZA2, DSTN, SNX9, BRK1, CYFIP2, NCK1, PFN1, ARPC4, TMOD3 | J7: redundant
A8: GOBP_ACTIVATION_OF_IMMUNE_RESPONSE | B8: Activation Of Immune Response | C8: 1.9195222e-06 | D8: 3.3170157e-05 | E8: 0.62725674 | F8: 0.36255186 | G8: 1.7422585 | H8: 341 | I8: NLRP1, SQSTM1, NFKBIA, NAGK, SEC14L1, LIPA, CD59, LAMP2, FOXP1, NFKB1, CARD8, CYBA, APP, BCAR1, RFTN1, CD46, IFI16, IRF2, ELF1, SIRT2, NEK7, BTN3A2, BTN2A1, GATA3, PIK3CA, RELA, PJA2, DUSP3, RPS6KA3, TICAM1, TRIM25, ADA, LRCH4, ZDHHC1, EZR, NOD1, CPTP, IRF1, CEACAM1, HCFC2, CLEC2B, CYLD, BAX, TAX1BP1, LATS2, CBLB, PRKCE, FBXL2, PHPT1, MASP1, RNF144A, FOSL2, BCL10, ABHD17A, DDX60, TRIM5, FYN, A2M, MARK4, CD55, CASP6, PLEKHA1, INPP5D, IFI35, C1RL, FOSL1, BTN3A1, CACNB3, MYD88, TRIM3, RAB29, TNIP1, IRAK4, GBP2, ZNFX1, PRNP, DGKZ, PIK3R1, LACC1, CD47, BECN1, NMI, PAK2, RAP1A, RNF135, ADCY7, PSEN1, TLR4, NFKBIZ, RIOK3, PDE4D, KLHL6, RBCK1, PDE4B, CD81, IRAK3, SERPING1, SMPDL3A, NINJ1, CMTM3, PLSCR1, PRKCH, EIF2AK2, SHB, MEF2C, TNIP2, UNC93B1, IRAK2, KCNK6, ITCH, NCK1, FCN3, PRKD2, PLCG2, LCP2, NFATC2, GDI1, PIK3CD, SARM1, NAGLU, TREX1, USP15, VAV3, LGALS9, CSNK1A1, NPLOC4, MAVS, IFIH1, ICOSLG, RIPK2, OAS3, NR1H3, ZC3HAV1 | J8: redundant
A9: GOBP_ACTIVATION_OF_INNATE_IMMUNE_RESPONSE | B9: Activation Of Innate Immune Response | C9: 0.0012033012 | D9: 0.0067525461 | E9: 0.45505987 | F9: 0.33625363 | G9: 1.5348883 | H9: 207 | I9: NLRP1, SQSTM1, NFKBIA, NAGK, SEC14L1, LAMP2, CARD8, CYBA, APP, RFTN1, IFI16, IRF2, SIRT2, NEK7, RELA, PJA2, RPS6KA3, TICAM1, TRIM25, LRCH4, ZDHHC1, NOD1, CPTP, IRF1, HCFC2, CYLD, TAX1BP1, LATS2, PRKCE, FBXL2, MASP1, RNF144A, BCL10, ABHD17A, DDX60, TRIM5, FYN, MARK4, CASP6, IFI35, FOSL1, MYD88, TRIM3, TNIP1, IRAK4, GBP2, ZNFX1, PIK3R1, LACC1, BECN1, NMI, PAK2, RNF135, ADCY7, TLR4, NFKBIZ, RIOK3, IRAK3, SMPDL3A, NINJ1, EIF2AK2, TNIP2, UNC93B1, IRAK2, KCNK6, ITCH, FCN3, PLCG2, GDI1, SARM1, NAGLU, TREX1, USP15, LGALS9, CSNK1A1, NPLOC4, MAVS, IFIH1, RIPK2, OAS3, NR1H3, ZC3HAV1 | J9: redundant
A10: GOBP_ACTIVATION_OF_PROTEIN_KINASE_ACTIVITY | B10: Activation Of Protein Kinase Activity | C10: 7.7508824e-05 | D10: 0.00072952109 | E10: 0.5384341 | F10: 0.62216322 | G10: 2.0203156 | H10: 31 | I10: TNFRSF1B, TNFRSF10B, PRKAR1A, TNFRSF1A, LTBR, PRKAR2B, TNFRSF10A, ITGB1BP1, CARD10, SESN2, RIPK1, PRKAR2A | J10: main
A11: GOBP_ACTOMYOSIN_STRUCTURE_ORGANIZATION | B11: Actomyosin Structure Organization | C11: 0.014593248 | D11: 0.045219686 | E11: 0.3807304 | F11: 0.3232502 | G11: 1.4084235 | H11: 150 | I11: CSRP1, RHOC, ITGB1, PRKAR1A, NRP1, PLEC, TNFAIP1, TMOD2, MYH9, IQGAP1, AKAP13, CFLAR, ARRB1, PPM1F, INPP5K, CNN3, CGNL1, ITGB1BP1, WDR1, SMAD3, SYNPO, PXN, CDC42, TPM1, S1PR1, CFL2, CDC42BPA, EPB41L4A, SORBS3, FERMT2, KRT8, ANKRD1, PIK3R1, FHOD1, CD47, PAK2, PDLIM1, S100A10, RHOA, WASF2, ARHGAP28, PDGFRB, ARHGEF15, TJP1, TMOD1, RAPGEF3, F11R, PDCD6IP, CDC42BPB, EDN1, TACR1, PFN1, TMOD3, LUZP1, ZEB2, LIMCH1 | J11: redundant
A12: GOBP_ACUTE_INFLAMMATORY_RESPONSE | B12: Acute Inflammatory Response | C12: 0.0029834952 | D12: 0.013647192 | E12: 0.4317077 | F12: 0.49911941 | G12: 1.7248719 | H12: 40 | I12: IL6ST, STAT3, LIPA, APOL2, GATA3, SIGIRR, B4GALT1, OSMR, FN1, ASH1L, IL10RB, IL6R, PRCP, EXT1, PLSCR1, HPSE, CTNNBIP1, CEBPB, NPY5R, C2CD4B | J12: redundant
A13: GOBP_ACYL_COA_METABOLIC_PROCESS | B13: Acyl Coa Metabolic Process | C13: 0.011567849 | D13: 0.038027183 | E13: 0.3807304 | F13: -0.35542959 | G13: -1.5277085 | H13: 78 | I13: PDK1, FASN, ELOVL6, HMGCS1, HSD17B4, PPT1, ACLY, AADAT, HMGCR, AASS, GPAM, ELOVL7, HACD2, HACD1, MVD, GCDH, ACSL4, ACSL1, SUCLA2, PDHX, DLAT, HSD17B12 | J13: redundant
... A1084: GOBP_ZYMOGEN_ACTIVATION | B1084: Zymogen Activation | C1084: 0.00081167879 | D1084: 0.0049667364 | E1084: 0.47727082 | F1084: 0.59262085 | G1084: 1.9068899 | H1084: 30 | I1084: FURIN, THBS1, ANXA2, CTSL, MMP14, PLAUR, MASP1, RUNX1, PLAU, C1RL, THBD, S100A10, ANXA2P2 | J1084: redundant

Sheet decisions2
A1: GOBP_ENDOTHELIAL_CELL_MIGRATION | B1: yes_apriori
A2: GOBP_SPROUTING_ANGIOGENESIS | B2: no_redundant
A3: GOBP_REGULATION_OF_ENDOTHELIAL_CELL_MIGRATION | B3: no_redundant
A4: GOBP_BLOOD_VESSEL_MORPHOGENESIS | B4: yes_apriori
A5: GOBP_POSITIVE_REGULATION_OF_ENDOTHELIAL_CELL_MIGRATION | B5: no_redundant
A6: GOBP_HEMOSTASIS | B6: yes_apriori
A7: GOBP_ENDOTHELIUM_DEVELOPMENT | B7: no_redundant
A8: GOBP_WOUND_HEALING | B8: no_redundant
A9: GOBP_VACUOLE_ORGANIZATION | B9: no_biology
A10: GOBP_REGULATION_OF_VASCULATURE_DEVELOPMENT | B10: no_redundant
A11: GOBP_REGULATION_OF_BODY_FLUID_LEVELS | B11: no_redundant
A12: GOBP_RESPONSE_TO_WOUNDING | B12: no_redundant
... A1083: GOBP_RIBONUCLEOPROTEIN_COMPLEX_BIOGENESIS | B1083: no_biology

Sheet EC_vs_iPSC
A2: Include in signature? | B2: include_apriori | C2: Stage-associated side of contrast (auto from NES sign) | D2: Biological category | E2: Redundancy | F2: pathway | G2: pathway_clean | H2: pval | I2: padj | J2: log2err | K2: ES | L2: NES | M2: size | N2: leadingEdge
F3: GOBP_2_OXOGLUTARATE_METABOLIC_PROCESS | G3: 2 Oxoglutarate Metabolic Process | H3: 0.098591549 | I3: 0.20734063 | J3: 0.21925035 | K3: -0.48114748 | L3: -1.3908074 | M3: 15 | N3: GPT2, L2HGDH, IDH1, GOT2
F4: GOBP_3_UTR_MEDIATED_MRNA_DESTABILIZATION | G4: 3 Utr Mediated Mrna Destabilization | H4: 0.57932692 | I4: 0.69205623 | J4: 0.081080206 | K4: -0.29342167 | L4: -0.91138964 | M4: 19 | N4: TRIM71, HNRNPD, DHX36, KHSRP, TARDBP
F5: GOBP_3_UTR_MEDIATED_MRNA_STABILIZATION | G5: 3 Utr Mediated Mrna Stabilization | H5: 0.098522167 | I5: 0.20734063 | J5: 0.22496609 | K5: -0.43063359 | L5: -1.3634966 | M5: 20 | N5: HNRNPC, METTL16, RBM38, RBM47
F6: GOBP_ACETYL_COA_BIOSYNTHETIC_PROCESS | G6: Acetyl Coa Biosynthetic Process | H6: 0.62333333 | I6: 0.72526066 | J6: 0.05909548 | K6: 0.29414727 | L6: 0.87690172 | M6: 21 | N6: PDP1, DIP2A, ACAT1, PDK4, ACSS2, PDK1, PDK2, PPCS, BCKDK, ACSS1, MPC2
F7: GOBP_ACETYL_COA_METABOLIC_PROCESS | G7: Acetyl Coa Metabolic Process | H7: 0.11294766 | I7: 0.22603373 | J7: 0.22205605 | K7: -0.35364877 | L7: -1.2876321 | M7: 35 | N7: AASS, FASN, GCDH, PIPOX, HMGCS1, ACACB, ACLY, PDHX, DLAT, NME1, HMGCR
F8: GOBP_ACIDIC_AMINO_ACID_TRANSPORT | G8: Acidic Amino Acid Transport | H8: 0.45504087 | I8: 0.59186121 | J8: 0.10208011 | K8: -0.2592493 | L8: -0.99558702 | M8: 40 | N8: SLC1A5, UCP2, SLC6A6, SLC1A1, PIANP, SLC25A22, SLC1A3, ABAT, KCNK1, LRRC8D, ATP1A2, SLC1A6
F9: GOBP_ACROSOME_ASSEMBLY | G9: Acrosome Assembly | H9: 0.64788732 | I9: 0.74193548 | J9: 0.073990144 | K9: -0.30158228 | L9: -0.87175529 | M9: 15 | N9: CCDC136, PLA2G3, CEP70, DCAF17
F10: GOBP_ACROSOME_REACTION | G10: Acrosome Reaction | H10: 0.47228916 | I10: 0.60490054 | J10: 0.092552886 | K10: -0.33262597 | L10: -0.98505397 | M10: 16 | N10: SYT6, CACNA1H, RAB3A, TRIM36, ADCY3, UNC13B, PCSK4
F11: GOBP_ACTIN_FILAMENT_BASED_MOVEMENT | G11: Actin Filament Based Movement | H11: 0.27323944 | I11: 0.42215979 | J11: 0.093145458 | K11: 0.27629978 | L11: 1.115277 | M11: 87 | N11: PARVA, SUN2, MYO6, GSN, MYO1C, PIK3CA, MYL6, CAMK2D, TRPM4, WIPF1, FRMD6, CAV1, GJA1, ZEB2, ACTA2, LIMCH1, PDE4D, MYH9
A12: yes_final | B12: yes_apriori | C12: =IF(L12>0,"EC-side","iPSC-side") -> EC-side | D12: angiogenesis / vasculogenesis | E12: =VLOOKUP(F12,collapsed3!A:J,10,FALSE) -> main | F12: GOBP_SPROUTING_ANGIOGENESIS | G12: Sprouting Angiogenesis | H12: 5.4128001e-13 | I12: 9.3043184e-11 | J12: 0.921426 | K12: 0.6054774 | L12: 2.5201977 | M12: 107 | N12: THBS1, FLT1, TGFB1, PARVA, ITGA5, EFNB2, TSPAN18, ITGB1, ADGRA2, KDR, JAK1, ENG, CEACAM1, ANXA1, NRP1, MMRN2, STARD13, FLT4, TGM2, PLK2, ADAMTS9, NGFR, TGFBR3, ITGB1BP1, AKT1, TEK, LOXL2, TBXA2R, NOTCH1, CDH13, PPP1R16B, ACVRL1, RECK, SEMA5A, VEGFC, NRARP, DLL4, ADGRG6, EPHB4, CIB1, CLEC14A, HDAC7, RNF213, CDH5, RHOA, GATA2, BMPER, PIK3R3, EHD4, RAMP2, EPHA2, ESM1
A13: yes_final | B13: =VLOOKUP(F13,decisions3!A:B,2,FALSE) -> yes_apriori | C13: =IF(L13>0,"EC-side","iPSC-side") -> EC-side | D13: angiogenesis / vasculogenesis | E13: =VLOOKUP(F13,collapsed3!A:J,10,FALSE) -> main | F13: GOBP_ENDOTHELIAL_CELL_MIGRATION | G13: Endothelial Cell Migration | H13: 1.4130318e-15 | I13: 4.1954199e-13 | J13: 1.0175448 | K13: 0.55889506 | L13: 2.4879489 | M13: 174 | N13: THBS1, TGFB1, VASH1, RHOB, EFNB2, PLXND1, ITGB1, TGFB1I1, ADGRA2, KDR, EFNA1, CEACAM1, ANXA1, NRP1, SPARC, MMRN2, STARD13, FLT4, FN1, PIK3CA, FOXP1, GADD45A, LGALS8, ATP2B4, SASH1, PLK2, ADAMTS9, ID1, TGFBR3, ITGB1BP1, AKT1, TEK, LOXL2, RRAS, TBXA2R, NOTCH1, PIK3CG, HSPB1, PRCP, CDH13, ETS1, PTPRM, LGMN, ACVRL1, SP100, SEMA5A, VEGFC, DLL4, GRN, NRP2, EPHB4, FSTL1, CD40, P2RX4, CIB1, CLEC14A, TNFSF12, ZEB2, CORO1B, HDAC7, WNT5A, TMSB4X, ADAM17, GATA3, MYH9, GPX1, NFE2L2, CDH5, RHOA, PPARG, EGF, ZNF580, NOS3, GATA2, BMPER, PIK3R3, EHD4, EDN1, SOX18, EPHA2, GIPC1, CALR, MICALL1, PDGFB, MEF2C, PDPK1, PTP4A3, EMC10, MECP2, RIN2
A14: yes_final | B14: yes_apriori | C14: =IF(L14>0,"EC-side","iPSC-side") -> EC-side | D14: endothelial specification | E14: =VLOOKUP(F14,collapsed3!A:J,10,FALSE) -> main | F14: GOBP_ENDOTHELIUM_DEVELOPMENT | G14: Endothelium Development | H14: 4.8693696e-12 | I14: 6.6264005e-10 | J14: 0.88707499 | K14: 0.57765121 | L14: 2.4364021 | M14: 112 | N14: RHOB, RAP1B, BMPR2, KDR, TIE1, CEACAM1, HEG1, PLOD3, NRP1, ADD1, STARD13, JAG1, BMP6, TNFRSF1A, FOXP1, ID1, MSN, LIPA, KDM6B, RAB1B, FZD4, NOTCH1, RDX, ICAM1, PPP1R16B, ACVRL1, GSTM3, COL18A1, DLL4, ROCK2, ADAMTS12, HEY1, TMEM100, MYD88, HOXB5, FSTL1, SLC40A1, CCM2, S1PR1, ROBO4, PDE4D, SOX17, GPX1, BTG1, MYADM, CDH5, RHOA, RAB1A, CLDN5, RAP1A, HEY2, EDN1, ZDHHC21, SOX18
A15: yes_final | B15: =VLOOKUP(F15,decisions3!A:B,2,FALSE) -> yes_apriori | C15: =IF(L15>0,"EC-side","iPSC-side") -> EC-side | D15: extracellular matrix organization / remodelling | E15: =VLOOKUP(F15,collapsed3!A:J,10,FALSE) -> main | F15: GOBP_COLLAGEN_METABOLIC_PROCESS | G15: Collagen Metabolic Process | H15: 1.0521812e-09 | I15: 7.6364975e-08 | J15: 0.78818681 | K15: 0.62624166 | L15: 2.4147368 | M15: 66 | N15: VIM, F2R, FURIN, TGFB1, CTSB, ITGB1, PLOD1, MMP14, TNS2, ITGA2, PLOD3, CTSL, CST3, P3H1, ID1, NOTCH1, P3H4, MMP9, TRAM2, COL5A1, COL1A1, FOSL2, ADAM15, EMILIN1, COL1A2, RUNX1, RAP1A, COL6A1, CYGB, RCN3, VIPAS39, P3H3, ERRFI1, IL6R, NAGLU, PLOD2, TMEM131, CREB3L1
F16: GOBP_ACTIN_MEDIATED_CELL_CONTRACTION | G16: Actin Mediated Cell Contraction | H16: 0.49418605 | I16: 0.62317051 | J16: 0.063642408 | K16: 0.25209155 | L16: 0.98050933 | M16: 71 | N16: PARVA, GSN, PIK3CA, MYL6, CAMK2D, TRPM4, FRMD6, CAV1, GJA1, ZEB2, ACTA2, LIMCH1, PDE4D, MYH9
F17: GOBP_ACTIN_NUCLEATION | G17: Actin Nucleation | H17: 0.019793835 | I17: 0.062976721 | J17: 0.35248786 | K17: 0.46021898 | L17: 1.5630102 | M17: 38 | N17: GSN, ARPC1B, ARPC2, ARPC3, HIP1R, ARPC5, ACTR2, ACTR3, FCHSD2, ARPIN, CORO1B, ARPC1A, ARPC4, ARF1, BRK1, SPIRE1, WHAMM
A18: yes_final | B18: =VLOOKUP(F18,decisions3!A:B,2,FALSE) -> no_redundant | C18: =IF(L18>0,"EC-side","iPSC-side") -> EC-side | D18: extracellular matrix organization / remodelling | E18: =VLOOKUP(F18,collapsed3!A:J,10,FALSE) -> main | F18: GOBP_COLLAGEN_FIBRIL_ORGANIZATION | G18: Collagen Fibril Organization | H18: 2.0151638e-08 | I18: 9.1754243e-07 | J18: 0.73376199 | K18: 0.6251734 | L18: 2.3493579 | M18: 58 | N18: COL4A1, COL4A2, ANXA2, COL5A2, PLOD1, ANTXR2, EFEMP2, PXDN, PLOD3, P3H1, COL4A5, LOXL2, BMP1, RB1, P3H4, COL5A1, ATP7A, COL1A1, COL11A1, ADAMTS12, FKBP10, EMILIN1, COLGALT1, COL1A2
F19: GOBP_ACTION_POTENTIAL | G19: Action Potential | H19: 0.38032787 | I19: 0.52655821 | J19: 0.12625399 | K19: -0.2311173 | L19: -1.0304007 | M19: 78 | N19: CXADR, FGF13, NEDD4L, NUP155, GJC1, HCN4, DSG2, SCN5A, KCNN2, KCNG1, SCN8A, KCNQ2, NOS1AP, MTOR, ATP1A2, KCNH2, SUMO1, PKP2, CLDN19, FKBP1B, CLCN2, RYR2, SCN4A, DLG1, ANK2, KCNS3, AKAP7
F20: GOBP_ACTIVATED_T_CELL_PROLIFERATION | G20: Activated T Cell Proliferation | H20: 0.084690554 | I20: 0.1847148 | J20: 0.195789 | K20: 0.45114135 | L20: 1.3890287 | M20: 24 | N20: LRRC32, PRKAR1A, PRNP, FYN, BTN3A1, IGF2, PPP3CA
F21: GOBP_ACTIVATION_OF_GTPASE_ACTIVITY | G21: Activation Of Gtpase Activity | H21: 0.18554217 | I21: 0.32147518 | J21: 0.15851411 | K21: -0.41754223 | L21: -1.2365289 | M21: 16 | N21: SIPA1L1, BCR, ECT2, RANGAP1
A22: no_redundant_auto | B22: =VLOOKUP(F22,decisions3!A:B,2,FALSE) -> no_redundant | C22: =IF(L22>0,"EC-side","iPSC-side") -> EC-side | D22: angiogenesis / vasculogenesis | E22: =VLOOKUP(F22,collapsed3!A:J,10,FALSE) -> redundant | F22: GOBP_REGULATION_OF_ENDOTHELIAL_CELL_MIGRATION | G22: Regulation Of Endothelial Cell Migration | H22: 2.5572309e-11 | I22: 2.783972e-09 | J22: 0.86341539 | K22: 0.54364322 | L22: 2.340722 | M22: 135 | N22: THBS1, TGFB1, VASH1, RHOB, ADGRA2, KDR, EFNA1, CEACAM1, ANXA1, NRP1, SPARC, MMRN2, STARD13, FLT4, FOXP1, GADD45A, ATP2B4, SASH1, PLK2, ADAMTS9, TGFBR3, ITGB1BP1, AKT1, TEK, RRAS, TBXA2R, NOTCH1, PIK3CG, HSPB1, PRCP, ETS1, PTPRM, LGMN, ACVRL1, SP100, SEMA5A, VEGFC, DLL4, GRN, NRP2, CD40, P2RX4, CIB1, HDAC7, WNT5A, TMSB4X, ADAM17, GATA3, NFE2L2, RHOA, PPARG, EGF, ZNF580, NOS3, GATA2, BMPER
